Workbook

Sheet Chess
A1: =IFERROR(INDEX(Engine!$CV$2:$CV$13,MATCH(Engine!AH$305,Engine!$CU$2:$CU$13,0)),"") -> rook | B1: =IFERROR(INDEX(Engine!$CV$2:$CV$13,MATCH(Engine!AI$305,Engine!$CU$2:$CU$13,0)),"") -> knight | C1: =IFERROR(INDEX(Engine!$CV$2:$CV$13,MATCH(Engine!AJ$305,Engine!$CU$2:$CU$13,0)),"") -> bishop | D1: =IFERROR(INDEX(Engine!$CV$2:$CV$13,MATCH(Engine!AK$305,Engine!$CU$2:$CU$13,0)),"") -> queen | E1: =IFERROR(INDEX(Engine!$CV$2:$CV$13,MATCH(Engine!AL$305,Engine!$CU$2:$CU$13,0)),"") -> king | F1: =IFERROR(INDEX(Engine!$CV$2:$CV$13,MATCH(Engine!AM$305,Engine!$CU$2:$CU$13,0)),"") -> bishop | G1: =IFERROR(INDEX(Engine!$CV$2:$CV$13,MATCH(Engine!AN$305,Engine!$CU$2:$CU$13,0)),"") -> knight | H1: =IFERROR(INDEX(Engine!$CV$2:$CV$13,MATCH(Engine!AO$305,Engine!$CU$2:$CU$13,0)),"") -> rook | J1: =IF(COUNTIF(Engine!$AH$305:$CS$305,"bK")=0,"White wins - Black king captured",IF(COUNTIF(Engine!$AH$305:$CS$305,"wK")=0,"Black wins - White king captured",IF(MOD(Engine!$B$2,2)=0,"White","Black")&" to move (move "&(INT(Engine!$B$2/2)+1)&")")) -> White to move (move 1) | Z1: helper: last from/to | AA1: =Engine!$F$2 -> 0 | AB1: =Engine!$H$2 -> 0
A2: =IFERROR(INDEX(Engine!$CV$2:$CV$13,MATCH(Engine!AP$305,Engine!$CU$2:$CU$13,0)),"") -> pawn | B2: =IFERROR(INDEX(Engine!$CV$2:$CV$13,MATCH(Engine!AQ$305,Engine!$CU$2:$CU$13,0)),"") -> pawn | C2: =IFERROR(INDEX(Engine!$CV$2:$CV$13,MATCH(Engine!AR$305,Engine!$CU$2:$CU$13,0)),"") -> pawn | D2: =IFERROR(INDEX(Engine!$CV$2:$CV$13,MATCH(Engine!AS$305,Engine!$CU$2:$CU$13,0)),"") -> pawn | E2: =IFERROR(INDEX(Engine!$CV$2:$CV$13,MATCH(Engine!AT$305,Engine!$CU$2:$CU$13,0)),"") -> pawn | F2: =IFERROR(INDEX(Engine!$CV$2:$CV$13,MATCH(Engine!AU$305,Engine!$CU$2:$CU$13,0)),"") -> pawn | G2: =IFERROR(INDEX(Engine!$CV$2:$CV$13,MATCH(Engine!AV$305,Engine!$CU$2:$CU$13,0)),"") -> pawn | H2: =IFERROR(INDEX(Engine!$CV$2:$CV$13,MATCH(Engine!AW$305,Engine!$CU$2:$CU$13,0)),"") -> pawn | J2: =IF(COUNTA($L$10:$L$309)=0,"Type White's first move in the yellow cell below, e.g. e2e4","Last entry: "&INDEX($M$10:$M$309,COUNTA($L$10:$L$309))) -> Type White's first move in the yellow cell below, e.g. e2e4
A3: =IFERROR(INDEX(Engine!$CV$2:$CV$13,MATCH(Engine!AX$305,Engine!$CU$2:$CU$13,0)),"") | B3: =IFERROR(INDEX(Engine!$CV$2:$CV$13,MATCH(Engine!AY$305,Engine!$CU$2:$CU$13,0)),"") | C3: =IFERROR(INDEX(Engine!$CV$2:$CV$13,MATCH(Engine!AZ$305,Engine!$CU$2:$CU$13,0)),"") | D3: =IFERROR(INDEX(Engine!$CV$2:$CV$13,MATCH(Engine!BA$305,Engine!$CU$2:$CU$13,0)),"") | E3: =IFERROR(INDEX(Engine!$CV$2:$CV$13,MATCH(Engine!BB$305,Engine!$CU$2:$CU$13,0)),"") | F3: =IFERROR(INDEX(Engine!$CV$2:$CV$13,MATCH(Engine!BC$305,Engine!$CU$2:$CU$13,0)),"") | G3: =IFERROR(INDEX(Engine!$CV$2:$CV$13,MATCH(Engine!BD$305,Engine!$CU$2:$CU$13,0)),"") | H3: =IFERROR(INDEX(Engine!$CV$2:$CV$13,MATCH(Engine!BE$305,Engine!$CU$2:$CU$13,0)),"") | J3: Board: columns A-H = files a-h, rows 1-8 = ranks. White = lowercase (rows 1-2), BLACK = UPPERCASE in red (rows 7-8).
A4: =IFERROR(INDEX(Engine!$CV$2:$CV$13,MATCH(Engine!BF$305,Engine!$CU$2:$CU$13,0)),"") | B4: =IFERROR(INDEX(Engine!$CV$2:$CV$13,MATCH(Engine!BG$305,Engine!$CU$2:$CU$13,0)),"") | C4: =IFERROR(INDEX(Engine!$CV$2:$CV$13,MATCH(Engine!BH$305,Engine!$CU$2:$CU$13,0)),"") | D4: =IFERROR(INDEX(Engine!$CV$2:$CV$13,MATCH(Engine!BI$305,Engine!$CU$2:$CU$13,0)),"") | E4: =IFERROR(INDEX(Engine!$CV$2:$CV$13,MATCH(Engine!BJ$305,Engine!$CU$2:$CU$13,0)),"") | F4: =IFERROR(INDEX(Engine!$CV$2:$CV$13,MATCH(Engine!BK$305,Engine!$CU$2:$CU$13,0)),"") | G4: =IFERROR(INDEX(Engine!$CV$2:$CV$13,MATCH(Engine!BL$305,Engine!$CU$2:$CU$13,0)),"") | H4: =IFERROR(INDEX(Engine!$CV$2:$CV$13,MATCH(Engine!BM$305,Engine!$CU$2:$CU$13,0)),"") | J4: Moves: from-square + to-square (e2e4). Castle = king moves 2 (e1g1). Promotion auto-queens, or add q/r/b/n (e7e8n). En passant works.
A5: =IFERROR(INDEX(Engine!$CV$2:$CV$13,MATCH(Engine!BN$305,Engine!$CU$2:$CU$13,0)),"") | B5: =IFERROR(INDEX(Engine!$CV$2:$CV$13,MATCH(Engine!BO$305,Engine!$CU$2:$CU$13,0)),"") | C5: =IFERROR(INDEX(Engine!$CV$2:$CV$13,MATCH(Engine!BP$305,Engine!$CU$2:$CU$13,0)),"") | D5: =IFERROR(INDEX(Engine!$CV$2:$CV$13,MATCH(Engine!BQ$305,Engine!$CU$2:$CU$13,0)),"") | E5: =IFERROR(INDEX(Engine!$CV$2:$CV$13,MATCH(Engine!BR$305,Engine!$CU$2:$CU$13,0)),"") | F5: =IFERROR(INDEX(Engine!$CV$2:$CV$13,MATCH(Engine!BS$305,Engine!$CU$2:$CU$13,0)),"") | G5: =IFERROR(INDEX(Engine!$CV$2:$CV$13,MATCH(Engine!BT$305,Engine!$CU$2:$CU$13,0)),"") | H5: =IFERROR(INDEX(Engine!$CV$2:$CV$13,MATCH(Engine!BU$305,Engine!$CU$2:$CU$13,0)),"") | J5: Bad move = red X, just overwrite it. To restart, clear the yellow cells. Check/checkmate are NOT enforced; capturing a king ends the game.
A6: =IFERROR(INDEX(Engine!$CV$2:$CV$13,MATCH(Engine!BV$305,Engine!$CU$2:$CU$13,0)),"") | B6: =IFERROR(INDEX(Engine!$CV$2:$CV$13,MATCH(Engine!BW$305,Engine!$CU$2:$CU$13,0)),"") | C6: =IFERROR(INDEX(Engine!$CV$2:$CV$13,MATCH(Engine!BX$305,Engine!$CU$2:$CU$13,0)),"") | D6: =IFERROR(INDEX(Engine!$CV$2:$CV$13,MATCH(Engine!BY$305,Engine!$CU$2:$CU$13,0)),"") | E6: =IFERROR(INDEX(Engine!$CV$2:$CV$13,MATCH(Engine!BZ$305,Engine!$CU$2:$CU$13,0)),"") | F6: =IFERROR(INDEX(Engine!$CV$2:$CV$13,MATCH(Engine!CA$305,Engine!$CU$2:$CU$13,0)),"") | G6: =IFERROR(INDEX(Engine!$CV$2:$CV$13,MATCH(Engine!CB$305,Engine!$CU$2:$CU$13,0)),"") | H6: =IFERROR(INDEX(Engine!$CV$2:$CV$13,MATCH(Engine!CC$305,Engine!$CU$2:$CU$13,0)),"") | J6: ="Captured by White: "&REPT("P",MAX(0,8-COUNTIF(Engine!$AH$305:$CS$305,"bP")))&" "&REPT("N",MAX(0,2-COUNTIF(Engine!$AH$305:$CS$305,"bN")))&" "&REPT("B",MAX(0,2-COUNTIF(Engine!$AH$305:$CS$305,"bB")))&" "&REPT("R",MAX(0,2-COUNTIF(Engine!$AH$305:$CS$305,"bR")))&" "&REPT("Q",MAX(0,1-COUNTIF(Engine!$AH$305:$CS$305,"bQ"))) -> Captured by White:
A7: =IFERROR(INDEX(Engine!$CV$2:$CV$13,MATCH(Engine!CD$305,Engine!$CU$2:$CU$13,0)),"") -> PAWN | B7: =IFERROR(INDEX(Engine!$CV$2:$CV$13,MATCH(Engine!CE$305,Engine!$CU$2:$CU$13,0)),"") -> PAWN | C7: =IFERROR(INDEX(Engine!$CV$2:$CV$13,MATCH(Engine!CF$305,Engine!$CU$2:$CU$13,0)),"") -> PAWN | D7: =IFERROR(INDEX(Engine!$CV$2:$CV$13,MATCH(Engine!CG$305,Engine!$CU$2:$CU$13,0)),"") -> PAWN | E7: =IFERROR(INDEX(Engine!$CV$2:$CV$13,MATCH(Engine!CH$305,Engine!$CU$2:$CU$13,0)),"") -> PAWN | F7: =IFERROR(INDEX(Engine!$CV$2:$CV$13,MATCH(Engine!CI$305,Engine!$CU$2:$CU$13,0)),"") -> PAWN | G7: =IFERROR(INDEX(Engine!$CV$2:$CV$13,MATCH(Engine!CJ$305,Engine!$CU$2:$CU$13,0)),"") -> PAWN | H7: =IFERROR(INDEX(Engine!$CV$2:$CV$13,MATCH(Engine!CK$305,Engine!$CU$2:$CU$13,0)),"") -> PAWN | J7: ="Captured by Black: "&REPT("P",MAX(0,8-COUNTIF(Engine!$AH$305:$CS$305,"wP")))&" "&REPT("N",MAX(0,2-COUNTIF(Engine!$AH$305:$CS$305,"wN")))&" "&REPT("B",MAX(0,2-COUNTIF(Engine!$AH$305:$CS$305,"wB")))&" "&REPT("R",MAX(0,2-COUNTIF(Engine!$AH$305:$CS$305,"wR")))&" "&REPT("Q",MAX(0,1-COUNTIF(Engine!$AH$305:$CS$305,"wQ"))) -> Captured by Black:
A8: =IFERROR(INDEX(Engine!$CV$2:$CV$13,MATCH(Engine!CL$305,Engine!$CU$2:$CU$13,0)),"") -> ROOK | B8: =IFERROR(INDEX(Engine!$CV$2:$CV$13,MATCH(Engine!CM$305,Engine!$CU$2:$CU$13,0)),"") -> KNIGHT | C8: =IFERROR(INDEX(Engine!$CV$2:$CV$13,MATCH(Engine!CN$305,Engine!$CU$2:$CU$13,0)),"") -> BISHOP | D8: =IFERROR(INDEX(Engine!$CV$2:$CV$13,MATCH(Engine!CO$305,Engine!$CU$2:$CU$13,0)),"") -> QUEEN | E8: =IFERROR(INDEX(Engine!$CV$2:$CV$13,MATCH(Engine!CP$305,Engine!$CU$2:$CU$13,0)),"") -> KING | F8: =IFERROR(INDEX(Engine!$CV$2:$CV$13,MATCH(Engine!CQ$305,Engine!$CU$2:$CU$13,0)),"") -> BISHOP | G8: =IFERROR(INDEX(Engine!$CV$2:$CV$13,MATCH(Engine!CR$305,Engine!$CU$2:$CU$13,0)),"") -> KNIGHT | H8: =IFERROR(INDEX(Engine!$CV$2:$CV$13,MATCH(Engine!CS$305,Engine!$CU$2:$CU$13,0)),"") -> ROOK
J9: # | K9: Side | L9: Move | M9: Result
J10: 1 | K10: =IF(OR(Engine!$B6<>"",ROW()-9=COUNTA($L$10:$L$309)+1),IF(Engine!$F6="w","White","Black"),"") -> White | M10: =Engine!$AF6
J11: 2 | K11: =IF(OR(Engine!$B7<>"",ROW()-9=COUNTA($L$10:$L$309)+1),IF(Engine!$F7="w","White","Black"),"") | M11: =Engine!$AF7
J12: 3 | K12: =IF(OR(Engine!$B8<>"",ROW()-9=COUNTA($L$10:$L$309)+1),IF(Engine!$F8="w","White","Black"),"") | M12: =Engine!$AF8
J13: 4 | K13: =IF(OR(Engine!$B9<>"",ROW()-9=COUNTA($L$10:$L$309)+1),IF(Engine!$F9="w","White","Black"),"") | M13: =Engine!$AF9
J14: 5 | K14: =IF(OR(Engine!$B10<>"",ROW()-9=COUNTA($L$10:$L$309)+1),IF(Engine!$F10="w","White","Black"),"") | M14: =Engine!$AF10
J15: 6 | K15: =IF(OR(Engine!$B11<>"",ROW()-9=COUNTA($L$10:$L$309)+1),IF(Engine!$F11="w","White","Black"),"") | M15: =Engine!$AF11
J16: 7 | K16: =IF(OR(Engine!$B12<>"",ROW()-9=COUNTA($L$10:$L$309)+1),IF(Engine!$F12="w","White","Black"),"") | M16: =Engine!$AF12
J17: 8 | K17: =IF(OR(Engine!$B13<>"",ROW()-9=COUNTA($L$10:$L$309)+1),IF(Engine!$F13="w","White","Black"),"") | M17: =Engine!$AF13
J18: 9 | K18: =IF(OR(Engine!$B14<>"",ROW()-9=COUNTA($L$10:$L$309)+1),IF(Engine!$F14="w","White","Black"),"") | M18: =Engine!$AF14
J19: 10 | K19: =IF(OR(Engine!$B15<>"",ROW()-9=COUNTA($L$10:$L$309)+1),IF(Engine!$F15="w","White","Black"),"") | M19: =Engine!$AF15
J20: 11 | K20: =IF(OR(Engine!$B16<>"",ROW()-9=COUNTA($L$10:$L$309)+1),IF(Engine!$F16="w","White","Black"),"") | M20: =Engine!$AF16
J21: 12 | K21: =IF(OR(Engine!$B17<>"",ROW()-9=COUNTA($L$10:$L$309)+1),IF(Engine!$F17="w","White","Black"),"") | M21: =Engine!$AF17
... J309: 300 | K309: =IF(OR(Engine!$B305<>"",ROW()-9=COUNTA($L$10:$L$309)+1),IF(Engine!$F305="w","White","Black"),"") | M309: =Engine!$AF305

Sheet Engine
A1: ENGINE - recalculates the position after every move. Don't edit; play on the Chess tab. | CU1: code | CV1: name
A2: Valid plies | B2: =SUM($P$6:$P$305) -> 0 | C2: Last valid ply | D2: =SUMPRODUCT(MAX(($P$6:$P$305=1)*$A$6:$A$305)) -> 0 | E2: Last from | F2: =IF($D$2=0,0,INDEX($D$6:$D$305,$D$2)) -> 0 | G2: Last to | H2: =IF($D$2=0,0,INDEX($E$6:$E$305,$D$2)) -> 0 | CU2: wK | CV2: king
AH3: 1 | AI3: 2 | AJ3: 3 | AK3: 4 | AL3: 5 | AM3: 6 | AN3: 7 | AO3: 8 | AP3: 9 | AQ3: 10 | AR3: 11 | AS3: 12 | AT3: 13 | AU3: 14 | AV3: 15 | AW3: 16 | AX3: 17 | AY3: 18 | AZ3: 19 | BA3: 20 | BB3: 21 | BC3: 22 | BD3: 23 | BE3: 24 | BF3: 25 | BG3: 26 | BH3: 27 | BI3: 28 | BJ3: 29 | BK3: 30 | BL3: 31 | BM3: 32 | BN3: 33 | BO3: 34 | BP3: 35 | BQ3: 36 | BR3: 37 | BS3: 38 | BT3: 39 | BU3: 40 | BV3: 41 | BW3: 42 | BX3: 43 | BY3: 44 | BZ3: 45 | CA3: 46 | CB3: 47 | CC3: 48 | CD3: 49 | CE3: 50 | CF3: 51 | CG3: 52 | CH3: 53 | CI3: 54 | CJ3: 55 | CK3: 56 | CL3: 57 | CM3: 58 | CN3: 59 | CO3: 60 | CP3: 61 | CQ3: 62 | CR3: 63 | CS3: 64 | CU3: wQ | CV3: queen
A4: Ply | B4: Input | C4: Clean | D4: From | E4: To | F4: Side | G4: Piece | H4: Target | I4: dFile | J4: dRank | K4: Type | L4: Blockers | M4: CastleOK | N4: PawnOK | O4: ShapeOK | P4: Valid | Q4: Reason | R4: EP target | S4: wK moved | T4: wRa moved | U4: wRh moved | V4: bK moved | W4: bRa moved | X4: bRh moved | Y4: Castle | Z4: En passant | AA4: Promo | AB4: Promo pc | AC4: Rook from | AD4: Rook to | AE4: EP captured | AF4: Description | AH4: a1 | AI4: b1 | AJ4: c1 | AK4: d1 | AL4: e1 | AM4: f1 | AN4: g1 | AO4: h1 | AP4: a2 | AQ4: b2 | AR4: c2 | AS4: d2 | AT4: e2 | AU4: f2 | AV4: g2 | AW4: h2 | AX4: a3 | AY4: b3 | AZ4: c3 | BA4: d3 | BB4: e3 | BC4: f3 | BD4: g3 | BE4: h3 | BF4: a4 | BG4: b4 | BH4: c4 | BI4: d4 | BJ4: e4 | BK4: f4 | BL4: g4 | BM4: h4 | BN4: a5 | BO4: b5 | BP4: c5 | BQ4: d5 | BR4: e5 | BS4: f5 | BT4: g5 | BU4: h5 | BV4: a6 | BW4: b6 | BX4: c6 | BY4: d6 | BZ4: e6 | CA4: f6 | CB4: g6 | CC4: h6 | CD4: a7 | CE4: b7 | CF4: c7 | CG4: d7 | CH4: e7 | CI4: f7 | CJ4: g7 | CK4: h7 | CL4: a8 | CM4: b8 | CN4: c8 | CO4: d8 | CP4: e8 | CQ4: f8 | CR4: g8 | CS4: h8 | CU4: wR | CV4: rook
P5: 0 | Q5: Start position | R5: 0 | S5: 0 | T5: 0 | U5: 0 | V5: 0 | W5: 0 | X5: 0 | AH5: wR | AI5: wN | AJ5: wB | AK5: wQ | AL5: wK | AM5: wB | AN5: wN | AO5: wR | AP5: wP | AQ5: wP | AR5: wP | AS5: wP | AT5: wP | AU5: wP | AV5: wP | AW5: wP | AX5: ="" | AY5: ="" | AZ5: ="" | BA5: ="" | BB5: ="" | BC5: ="" | BD5: ="" | BE5: ="" | ... CC5: ="" | CD5: bP | CE5: bP | CF5: bP | CG5: bP | CH5: bP | CI5: bP | CJ5: bP | CK5: bP | CL5: bR | CM5: bN | CN5: bB | CO5: bQ | CP5: bK | CQ5: bB | CR5: bN | CS5: bR | CU5: wB | CV5: bishop
A6: 1 | B6: =IF(Chess!$L$10="","",Chess!$L$10&"") | C6: =LOWER(SUBSTITUTE(SUBSTITUTE(SUBSTITUTE(SUBSTITUTE(TRIM($B6),"-",""),"=","")," ",""),"x","")) | D6: =IF(LEN($C6)<4,0,IFERROR(IF(AND(CODE(MID($C6,1,1))>=97,CODE(MID($C6,1,1))<=104,VALUE(MID($C6,2,1))>=1,VALUE(MID($C6,2,1))<=8),(VALUE(MID($C6,2,1))-1)*8+CODE(MID($C6,1,1))-96,0),0)) -> 0 | E6: =IF(LEN($C6)<4,0,IFERROR(IF(AND(CODE(MID($C6,3,1))>=97,CODE(MID($C6,3,1))<=104,VALUE(MID($C6,4,1))>=1,VALUE(MID($C6,4,1))<=8),(VALUE(MID($C6,4,1))-1)*8+CODE(MID($C6,3,1))-96,0),0)) -> 0 | F6: =IF(MOD(SUM($P$5:$P5),2)=0,"w","b") -> w | G6: =IF($D6=0,"",INDEX($AH5:$CS5,1,$D6)&"") | H6: =IF($E6=0,"",INDEX($AH5:$CS5,1,$E6)&"") | I6: =IF(OR($D6=0,$E6=0),0,MOD($E6-1,8)-MOD($D6-1,8)) -> 0 | J6: =IF(OR($D6=0,$E6=0),0,INT(($E6-1)/8)-INT(($D6-1)/8)) -> 0 | K6: =IF($G6="","",RIGHT($G6,1)) | L6: =IF(OR($D6=0,$E6=0),0,SUMPRODUCT(($AH$3:$CS$3>MIN($D6,$E6))*($AH$3:$CS$3<MAX($D6,$E6))*(MOD($AH$3:$CS$3-MIN($D6,$E6),MAX(1,ABS(SIGN($J6)*8+SIGN($I6))))=0)*($AH5:$CS5<>""))) -> 0 | M6: =IF($K6<>"K",0,IFERROR(--AND($J6=0,ABS($I6)=2,$D6=IF($F6="w",5,61),IF($F6="w",$S5,$V5)=0,IF($I6=2,AND(IF($F6="w",$U5,$X5)=0,INDEX($AH5:$CS5,1,$D6+1)&""="",INDEX($AH5:$CS5,1,$D6+2)&""=""),AND(IF($F6="w",$T5,$W5)=0,INDEX($AH5:$CS5,1,$D6-1)&""="",INDEX($AH5:$CS5,1,$D6-2)&""="",INDEX($AH5:$CS5,1,$D6-3)&""=""))),0)) -> 0 | N6: =IF($K6<>"P",0,IFERROR(--OR(AND($I6=0,$J6=IF($F6="w",1,-1),$H6=""),AND($I6=0,$J6=2*IF($F6="w",1,-1),$H6="",INT(($D6-1)/8)=IF($F6="w",1,6),INDEX($AH5:$CS5,1,MAX(1,MIN(64,$D6+8*IF($F6="w",1,-1))))&""=""),AND(ABS($I6)=1,$J6=IF($F6="w",1,-1),$H6<>""),AND(ABS($I6)=1,$J6=IF($F6="w",1,-1),$H6="",$R5>0,$E6=$R5)),0)) -> 0 | O6: =IF(OR($D6=0,$E6=0,$G6=""),0,IF($K6="N",--OR(AND(ABS($I6)=1,ABS($J6)=2),AND(ABS($I6)=2,ABS($J6)=1)),IF($K6="B",--AND(ABS($I6)=ABS($J6),$I6<>0,$L6=0),IF($K6="R",--AND(OR($I6=0,$J6=0),OR($I6<>0,$J6<>0),$L6=0),IF($K6="Q",--AND(OR(AND(ABS($I6)=ABS($J6),$I6<>0),AND(OR($I6=0,$J6=0),OR($I6<>0,$J6<>0))),$L6=0),IF($K6="K",--OR(MAX(ABS($I6),ABS($J6))=1,$M6=1),$N6)))))) -> 0 | P6: =IF($Q6="OK",1,0) -> 0 | Q6: =IF($B6="","",IF(OR(COUNTIF($AH5:$CS5,"wK")=0,COUNTIF($AH5:$CS5,"bK")=0),"Game is over",IF(OR($D6=0,$E6=0),"Use the format e2e4",IF($G6="","No piece on that square",IF(LEFT($G6,1)<>$F6,"Not your piece ("&IF($F6="w","White","Black")&" to move)",IF($D6=$E6,"Piece must move",IF(AND($H6<>"",LEFT($H6,1)=$F6),"Cannot capture your own piece",IF($O6=0,"Illegal move for that piece (or path blocked)","OK")))))))) | R6: =IF($P6=1,IF(AND($K6="P",ABS($J6)=2),($D6+$E6)/2,0),$R5) -> 0 | S6: =--OR($S5=1,AND($P6=1,OR($D6=5,$E6=5))) -> FALSE | T6: =--OR($T5=1,AND($P6=1,OR($D6=1,$E6=1))) -> FALSE | U6: =--OR($U5=1,AND($P6=1,OR($D6=8,$E6=8))) -> FALSE | V6: =--OR($V5=1,AND($P6=1,OR($D6=61,$E6=61))) -> FALSE | W6: =--OR($W5=1,AND($P6=1,OR($D6=57,$E6=57))) -> FALSE | X6: =--OR($X5=1,AND($P6=1,OR($D6=64,$E6=64))) -> FALSE | Y6: =--AND($P6=1,$K6="K",ABS($I6)=2) -> FALSE | Z6: =--AND($P6=1,$K6="P",ABS($I6)=1,$H6="") -> FALSE | AA6: =--AND($P6=1,$K6="P",INT(($E6-1)/8)=IF($F6="w",7,0)) -> FALSE | AB6: =IF(LEN($C6)>=5,IF(ISNUMBER(FIND(MID($C6,5,1),"qrbn")),UPPER(MID($C6,5,1)),"Q"),"Q") -> Q | AC6: =IF($Y6=1,IF($I6=2,$D6+3,$D6-4),0) -> 0 | AD6: =IF($Y6=1,IF($I6=2,$D6+1,$D6-1),0) -> 0 | AE6: =IF($Z6=1,$E6-8*IF($F6="w",1,-1),0) -> 0 | AF6: =IF($B6="","",IF($P6=1,LOWER(INDEX($CV$2:$CV$13,MATCH($G6,$CU$2:$CU$13,0)))&" "&MID("abcdefgh",MOD($D6-1,8)+1,1)&(INT(($D6-1)/8)+1)&"→"&MID("abcdefgh",MOD($E6-1,8)+1,1)&(INT(($E6-1)/8)+1)&IF(OR($H6<>"",$Z6=1)," ×","")&IF($Y6=1," castles","")&IF($Z6=1," e.p.","")&IF($AA6=1," =" &LOWER(INDEX($CV$2:$CV$13,MATCH($F6&$AB6,$CU$2:$CU$13,0))),""),"X "&$Q6)) | AH6: =IF($P6=0,AH5,IF(AH$3=$E6,IF($AA6=1,$F6&$AB6,$G6),IF(OR(AH$3=$D6,AH$3=$AC6,AH$3=$AE6),"",IF(AH$3=$AD6,$F6&"R",AH5)))) -> wR | AI6: =IF($P6=0,AI5,IF(AI$3=$E6,IF($AA6=1,$F6&$AB6,$G6),IF(OR(AI$3=$D6,AI$3=$AC6,AI$3=$AE6),"",IF(AI$3=$AD6,$F6&"R",AI5)))) -> wN | AJ6: =IF($P6=0,AJ5,IF(AJ$3=$E6,IF($AA6=1,$F6&$AB6,$G6),IF(OR(AJ$3=$D6,AJ$3=$AC6,AJ$3=$AE6),"",IF(AJ$3=$AD6,$F6&"R",AJ5)))) -> wB | AK6: =IF($P6=0,AK5,IF(AK$3=$E6,IF($AA6=1,$F6&$AB6,$G6),IF(OR(AK$3=$D6,AK$3=$AC6,AK$3=$AE6),"",IF(AK$3=$AD6,$F6&"R",AK5)))) -> wQ | AL6: =IF($P6=0,AL5,IF(AL$3=$E6,IF($AA6=1,$F6&$AB6,$G6),IF(OR(AL$3=$D6,AL$3=$AC6,AL$3=$AE6),"",IF(AL$3=$AD6,$F6&"R",AL5)))) -> wK | AM6: =IF($P6=0,AM5,IF(AM$3=$E6,IF($AA6=1,$F6&$AB6,$G6),IF(OR(AM$3=$D6,AM$3=$AC6,AM$3=$AE6),"",IF(AM$3=$AD6,$F6&"R",AM5)))) -> wB | AN6: =IF($P6=0,AN5,IF(AN$3=$E6,IF($AA6=1,$F6&$AB6,$G6),IF(OR(AN$3=$D6,AN$3=$AC6,AN$3=$AE6),"",IF(AN$3=$AD6,$F6&"R",AN5)))) -> wN | AO6: =IF($P6=0,AO5,IF(AO$3=$E6,IF($AA6=1,$F6&$AB6,$G6),IF(OR(AO$3=$D6,AO$3=$AC6,AO$3=$AE6),"",IF(AO$3=$AD6,$F6&"R",AO5)))) -> wR | ... CS6: =IF($P6=0,CS5,IF(CS$3=$E6,IF($AA6=1,$F6&$AB6,$G6),IF(OR(CS$3=$D6,CS$3=$AC6,CS$3=$AE6),"",IF(CS$3=$AD6,$F6&"R",CS5)))) -> bR | CU6: wN | CV6: knight
A7: 2 | B7: =IF(Chess!$L$11="","",Chess!$L$11&"") | C7: =LOWER(SUBSTITUTE(SUBSTITUTE(SUBSTITUTE(SUBSTITUTE(TRIM($B7),"-",""),"=","")," ",""),"x","")) | D7: =IF(LEN($C7)<4,0,IFERROR(IF(AND(CODE(MID($C7,1,1))>=97,CODE(MID($C7,1,1))<=104,VALUE(MID($C7,2,1))>=1,VALUE(MID($C7,2,1))<=8),(VALUE(MID($C7,2,1))-1)*8+CODE(MID($C7,1,1))-96,0),0)) -> 0 | E7: =IF(LEN($C7)<4,0,IFERROR(IF(AND(CODE(MID($C7,3,1))>=97,CODE(MID($C7,3,1))<=104,VALUE(MID($C7,4,1))>=1,VALUE(MID($C7,4,1))<=8),(VALUE(MID($C7,4,1))-1)*8+CODE(MID($C7,3,1))-96,0),0)) -> 0 | F7: =IF(MOD(SUM($P$5:$P6),2)=0,"w","b") -> w | G7: =IF($D7=0,"",INDEX($AH6:$CS6,1,$D7)&"") | H7: =IF($E7=0,"",INDEX($AH6:$CS6,1,$E7)&"") | I7: =IF(OR($D7=0,$E7=0),0,MOD($E7-1,8)-MOD($D7-1,8)) -> 0 | J7: =IF(OR($D7=0,$E7=0),0,INT(($E7-1)/8)-INT(($D7-1)/8)) -> 0 | K7: =IF($G7="","",RIGHT($G7,1)) | L7: =IF(OR($D7=0,$E7=0),0,SUMPRODUCT(($AH$3:$CS$3>MIN($D7,$E7))*($AH$3:$CS$3<MAX($D7,$E7))*(MOD($AH$3:$CS$3-MIN($D7,$E7),MAX(1,ABS(SIGN($J7)*8+SIGN($I7))))=0)*($AH6:$CS6<>""))) -> 0 | M7: =IF($K7<>"K",0,IFERROR(--AND($J7=0,ABS($I7)=2,$D7=IF($F7="w",5,61),IF($F7="w",$S6,$V6)=0,IF($I7=2,AND(IF($F7="w",$U6,$X6)=0,INDEX($AH6:$CS6,1,$D7+1)&""="",INDEX($AH6:$CS6,1,$D7+2)&""=""),AND(IF($F7="w",$T6,$W6)=0,INDEX($AH6:$CS6,1,$D7-1)&""="",INDEX($AH6:$CS6,1,$D7-2)&""="",INDEX($AH6:$CS6,1,$D7-3)&""=""))),0)) -> 0 | N7: =IF($K7<>"P",0,IFERROR(--OR(AND($I7=0,$J7=IF($F7="w",1,-1),$H7=""),AND($I7=0,$J7=2*IF($F7="w",1,-1),$H7="",INT(($D7-1)/8)=IF($F7="w",1,6),INDEX($AH6:$CS6,1,MAX(1,MIN(64,$D7+8*IF($F7="w",1,-1))))&""=""),AND(ABS($I7)=1,$J7=IF($F7="w",1,-1),$H7<>""),AND(ABS($I7)=1,$J7=IF($F7="w",1,-1),$H7="",$R6>0,$E7=$R6)),0)) -> 0 | O7: =IF(OR($D7=0,$E7=0,$G7=""),0,IF($K7="N",--OR(AND(ABS($I7)=1,ABS($J7)=2),AND(ABS($I7)=2,ABS($J7)=1)),IF($K7="B",--AND(ABS($I7)=ABS($J7),$I7<>0,$L7=0),IF($K7="R",--AND(OR($I7=0,$J7=0),OR($I7<>0,$J7<>0),$L7=0),IF($K7="Q",--AND(OR(AND(ABS($I7)=ABS($J7),$I7<>0),AND(OR($I7=0,$J7=0),OR($I7<>0,$J7<>0))),$L7=0),IF($K7="K",--OR(MAX(ABS($I7),ABS($J7))=1,$M7=1),$N7)))))) -> 0 | P7: =IF($Q7="OK",1,0) -> 0 | Q7: =IF($B7="","",IF(OR(COUNTIF($AH6:$CS6,"wK")=0,COUNTIF($AH6:$CS6,"bK")=0),"Game is over",IF(OR($D7=0,$E7=0),"Use the format e2e4",IF($G7="","No piece on that square",IF(LEFT($G7,1)<>$F7,"Not your piece ("&IF($F7="w","White","Black")&" to move)",IF($D7=$E7,"Piece must move",IF(AND($H7<>"",LEFT($H7,1)=$F7),"Cannot capture your own piece",IF($O7=0,"Illegal move for that piece (or path blocked)","OK")))))))) | R7: =IF($P7=1,IF(AND($K7="P",ABS($J7)=2),($D7+$E7)/2,0),$R6) -> 0 | S7: =--OR($S6=1,AND($P7=1,OR($D7=5,$E7=5))) -> FALSE | T7: =--OR($T6=1,AND($P7=1,OR($D7=1,$E7=1))) -> FALSE | U7: =--OR($U6=1,AND($P7=1,OR($D7=8,$E7=8))) -> FALSE | V7: =--OR($V6=1,AND($P7=1,OR($D7=61,$E7=61))) -> FALSE | W7: =--OR($W6=1,AND($P7=1,OR($D7=57,$E7=57))) -> FALSE | X7: =--OR($X6=1,AND($P7=1,OR($D7=64,$E7=64))) -> FALSE | Y7: =--AND($P7=1,$K7="K",ABS($I7)=2) -> FALSE | Z7: =--AND($P7=1,$K7="P",ABS($I7)=1,$H7="") -> FALSE | AA7: =--AND($P7=1,$K7="P",INT(($E7-1)/8)=IF($F7="w",7,0)) -> FALSE | AB7: =IF(LEN($C7)>=5,IF(ISNUMBER(FIND(MID($C7,5,1),"qrbn")),UPPER(MID($C7,5,1)),"Q"),"Q") -> Q | AC7: =IF($Y7=1,IF($I7=2,$D7+3,$D7-4),0) -> 0 | AD7: =IF($Y7=1,IF($I7=2,$D7+1,$D7-1),0) -> 0 | AE7: =IF($Z7=1,$E7-8*IF($F7="w",1,-1),0) -> 0 | AF7: =IF($B7="","",IF($P7=1,LOWER(INDEX($CV$2:$CV$13,MATCH($G7,$CU$2:$CU$13,0)))&" "&MID("abcdefgh",MOD($D7-1,8)+1,1)&(INT(($D7-1)/8)+1)&"→"&MID("abcdefgh",MOD($E7-1,8)+1,1)&(INT(($E7-1)/8)+1)&IF(OR($H7<>"",$Z7=1)," ×","")&IF($Y7=1," castles","")&IF($Z7=1," e.p.","")&IF($AA7=1," =" &LOWER(INDEX($CV$2:$CV$13,MATCH($F7&$AB7,$CU$2:$CU$13,0))),""),"X "&$Q7)) | AH7: =IF($P7=0,AH6,IF(AH$3=$E7,IF($AA7=1,$F7&$AB7,$G7),IF(OR(AH$3=$D7,AH$3=$AC7,AH$3=$AE7),"",IF(AH$3=$AD7,$F7&"R",AH6)))) -> wR | AI7: =IF($P7=0,AI6,IF(AI$3=$E7,IF($AA7=1,$F7&$AB7,$G7),IF(OR(AI$3=$D7,AI$3=$AC7,AI$3=$AE7),"",IF(AI$3=$AD7,$F7&"R",AI6)))) -> wN | AJ7: =IF($P7=0,AJ6,IF(AJ$3=$E7,IF($AA7=1,$F7&$AB7,$G7),IF(OR(AJ$3=$D7,AJ$3=$AC7,AJ$3=$AE7),"",IF(AJ$3=$AD7,$F7&"R",AJ6)))) -> wB | AK7: =IF($P7=0,AK6,IF(AK$3=$E7,IF($AA7=1,$F7&$AB7,$G7),IF(OR(AK$3=$D7,AK$3=$AC7,AK$3=$AE7),"",IF(AK$3=$AD7,$F7&"R",AK6)))) -> wQ | AL7: =IF($P7=0,AL6,IF(AL$3=$E7,IF($AA7=1,$F7&$AB7,$G7),IF(OR(AL$3=$D7,AL$3=$AC7,AL$3=$AE7),"",IF(AL$3=$AD7,$F7&"R",AL6)))) -> wK | AM7: =IF($P7=0,AM6,IF(AM$3=$E7,IF($AA7=1,$F7&$AB7,$G7),IF(OR(AM$3=$D7,AM$3=$AC7,AM$3=$AE7),"",IF(AM$3=$AD7,$F7&"R",AM6)))) -> wB | AN7: =IF($P7=0,AN6,IF(AN$3=$E7,IF($AA7=1,$F7&$AB7,$G7),IF(OR(AN$3=$D7,AN$3=$AC7,AN$3=$AE7),"",IF(AN$3=$AD7,$F7&"R",AN6)))) -> wN | AO7: =IF($P7=0,AO6,IF(AO$3=$E7,IF($AA7=1,$F7&$AB7,$G7),IF(OR(AO$3=$D7,AO$3=$AC7,AO$3=$AE7),"",IF(AO$3=$AD7,$F7&"R",AO6)))) -> wR | ... CS7: =IF($P7=0,CS6,IF(CS$3=$E7,IF($AA7=1,$F7&$AB7,$G7),IF(OR(CS$3=$D7,CS$3=$AC7,CS$3=$AE7),"",IF(CS$3=$AD7,$F7&"R",CS6)))) -> bR | CU7: wP | CV7: pawn
A8: 3 | B8: =IF(Chess!$L$12="","",Chess!$L$12&"") | C8: =LOWER(SUBSTITUTE(SUBSTITUTE(SUBSTITUTE(SUBSTITUTE(TRIM($B8),"-",""),"=","")," ",""),"x","")) | D8: =IF(LEN($C8)<4,0,IFERROR(IF(AND(CODE(MID($C8,1,1))>=97,CODE(MID($C8,1,1))<=104,VALUE(MID($C8,2,1))>=1,VALUE(MID($C8,2,1))<=8),(VALUE(MID($C8,2,1))-1)*8+CODE(MID($C8,1,1))-96,0),0)) -> 0 | E8: =IF(LEN($C8)<4,0,IFERROR(IF(AND(CODE(MID($C8,3,1))>=97,CODE(MID($C8,3,1))<=104,VALUE(MID($C8,4,1))>=1,VALUE(MID($C8,4,1))<=8),(VALUE(MID($C8,4,1))-1)*8+CODE(MID($C8,3,1))-96,0),0)) -> 0 | F8: =IF(MOD(SUM($P$5:$P7),2)=0,"w","b") -> w | G8: =IF($D8=0,"",INDEX($AH7:$CS7,1,$D8)&"") | H8: =IF($E8=0,"",INDEX($AH7:$CS7,1,$E8)&"") | I8: =IF(OR($D8=0,$E8=0),0,MOD($E8-1,8)-MOD($D8-1,8)) -> 0 | J8: =IF(OR($D8=0,$E8=0),0,INT(($E8-1)/8)-INT(($D8-1)/8)) -> 0 | K8: =IF($G8="","",RIGHT($G8,1)) | L8: =IF(OR($D8=0,$E8=0),0,SUMPRODUCT(($AH$3:$CS$3>MIN($D8,$E8))*($AH$3:$CS$3<MAX($D8,$E8))*(MOD($AH$3:$CS$3-MIN($D8,$E8),MAX(1,ABS(SIGN($J8)*8+SIGN($I8))))=0)*($AH7:$CS7<>""))) -> 0 | M8: =IF($K8<>"K",0,IFERROR(--AND($J8=0,ABS($I8)=2,$D8=IF($F8="w",5,61),IF($F8="w",$S7,$V7)=0,IF($I8=2,AND(IF($F8="w",$U7,$X7)=0,INDEX($AH7:$CS7,1,$D8+1)&""="",INDEX($AH7:$CS7,1,$D8+2)&""=""),AND(IF($F8="w",$T7,$W7)=0,INDEX($AH7:$CS7,1,$D8-1)&""="",INDEX($AH7:$CS7,1,$D8-2)&""="",INDEX($AH7:$CS7,1,$D8-3)&""=""))),0)) -> 0 | N8: =IF($K8<>"P",0,IFERROR(--OR(AND($I8=0,$J8=IF($F8="w",1,-1),$H8=""),AND($I8=0,$J8=2*IF($F8="w",1,-1),$H8="",INT(($D8-1)/8)=IF($F8="w",1,6),INDEX($AH7:$CS7,1,MAX(1,MIN(64,$D8+8*IF($F8="w",1,-1))))&""=""),AND(ABS($I8)=1,$J8=IF($F8="w",1,-1),$H8<>""),AND(ABS($I8)=1,$J8=IF($F8="w",1,-1),$H8="",$R7>0,$E8=$R7)),0)) -> 0 | O8: =IF(OR($D8=0,$E8=0,$G8=""),0,IF($K8="N",--OR(AND(ABS($I8)=1,ABS($J8)=2),AND(ABS($I8)=2,ABS($J8)=1)),IF($K8="B",--AND(ABS($I8)=ABS($J8),$I8<>0,$L8=0),IF($K8="R",--AND(OR($I8=0,$J8=0),OR($I8<>0,$J8<>0),$L8=0),IF($K8="Q",--AND(OR(AND(ABS($I8)=ABS($J8),$I8<>0),AND(OR($I8=0,$J8=0),OR($I8<>0,$J8<>0))),$L8=0),IF($K8="K",--OR(MAX(ABS($I8),ABS($J8))=1,$M8=1),$N8)))))) -> 0 | P8: =IF($Q8="OK",1,0) -> 0 | Q8: =IF($B8="","",IF(OR(COUNTIF($AH7:$CS7,"wK")=0,COUNTIF($AH7:$CS7,"bK")=0),"Game is over",IF(OR($D8=0,$E8=0),"Use the format e2e4",IF($G8="","No piece on that square",IF(LEFT($G8,1)<>$F8,"Not your piece ("&IF($F8="w","White","Black")&" to move)",IF($D8=$E8,"Piece must move",IF(AND($H8<>"",LEFT($H8,1)=$F8),"Cannot capture your own piece",IF($O8=0,"Illegal move for that piece (or path blocked)","OK")))))))) | R8: =IF($P8=1,IF(AND($K8="P",ABS($J8)=2),($D8+$E8)/2,0),$R7) -> 0 | S8: =--OR($S7=1,AND($P8=1,OR($D8=5,$E8=5))) -> FALSE | T8: =--OR($T7=1,AND($P8=1,OR($D8=1,$E8=1))) -> FALSE | U8: =--OR($U7=1,AND($P8=1,OR($D8=8,$E8=8))) -> FALSE | V8: =--OR($V7=1,AND($P8=1,OR($D8=61,$E8=61))) -> FALSE | W8: =--OR($W7=1,AND($P8=1,OR($D8=57,$E8=57))) -> FALSE | X8: =--OR($X7=1,AND($P8=1,OR($D8=64,$E8=64))) -> FALSE | Y8: =--AND($P8=1,$K8="K",ABS($I8)=2) -> FALSE | Z8: =--AND($P8=1,$K8="P",ABS($I8)=1,$H8="") -> FALSE | AA8: =--AND($P8=1,$K8="P",INT(($E8-1)/8)=IF($F8="w",7,0)) -> FALSE | AB8: =IF(LEN($C8)>=5,IF(ISNUMBER(FIND(MID($C8,5,1),"qrbn")),UPPER(MID($C8,5,1)),"Q"),"Q") -> Q | AC8: =IF($Y8=1,IF($I8=2,$D8+3,$D8-4),0) -> 0 | AD8: =IF($Y8=1,IF($I8=2,$D8+1,$D8-1),0) -> 0 | AE8: =IF($Z8=1,$E8-8*IF($F8="w",1,-1),0) -> 0 | AF8: =IF($B8="","",IF($P8=1,LOWER(INDEX($CV$2:$CV$13,MATCH($G8,$CU$2:$CU$13,0)))&" "&MID("abcdefgh",MOD($D8-1,8)+1,1)&(INT(($D8-1)/8)+1)&"→"&MID("abcdefgh",MOD($E8-1,8)+1,1)&(INT(($E8-1)/8)+1)&IF(OR($H8<>"",$Z8=1)," ×","")&IF($Y8=1," castles","")&IF($Z8=1," e.p.","")&IF($AA8=1," =" &LOWER(INDEX($CV$2:$CV$13,MATCH($F8&$AB8,$CU$2:$CU$13,0))),""),"X "&$Q8)) | AH8: =IF($P8=0,AH7,IF(AH$3=$E8,IF($AA8=1,$F8&$AB8,$G8),IF(OR(AH$3=$D8,AH$3=$AC8,AH$3=$AE8),"",IF(AH$3=$AD8,$F8&"R",AH7)))) -> wR | AI8: =IF($P8=0,AI7,IF(AI$3=$E8,IF($AA8=1,$F8&$AB8,$G8),IF(OR(AI$3=$D8,AI$3=$AC8,AI$3=$AE8),"",IF(AI$3=$AD8,$F8&"R",AI7)))) -> wN | AJ8: =IF($P8=0,AJ7,IF(AJ$3=$E8,IF($AA8=1,$F8&$AB8,$G8),IF(OR(AJ$3=$D8,AJ$3=$AC8,AJ$3=$AE8),"",IF(AJ$3=$AD8,$F8&"R",AJ7)))) -> wB | AK8: =IF($P8=0,AK7,IF(AK$3=$E8,IF($AA8=1,$F8&$AB8,$G8),IF(OR(AK$3=$D8,AK$3=$AC8,AK$3=$AE8),"",IF(AK$3=$AD8,$F8&"R",AK7)))) -> wQ | AL8: =IF($P8=0,AL7,IF(AL$3=$E8,IF($AA8=1,$F8&$AB8,$G8),IF(OR(AL$3=$D8,AL$3=$AC8,AL$3=$AE8),"",IF(AL$3=$AD8,$F8&"R",AL7)))) -> wK | AM8: =IF($P8=0,AM7,IF(AM$3=$E8,IF($AA8=1,$F8&$AB8,$G8),IF(OR(AM$3=$D8,AM$3=$AC8,AM$3=$AE8),"",IF(AM$3=$AD8,$F8&"R",AM7)))) -> wB | AN8: =IF($P8=0,AN7,IF(AN$3=$E8,IF($AA8=1,$F8&$AB8,$G8),IF(OR(AN$3=$D8,AN$3=$AC8,AN$3=$AE8),"",IF(AN$3=$AD8,$F8&"R",AN7)))) -> wN | AO8: =IF($P8=0,AO7,IF(AO$3=$E8,IF($AA8=1,$F8&$AB8,$G8),IF(OR(AO$3=$D8,AO$3=$AC8,AO$3=$AE8),"",IF(AO$3=$AD8,$F8&"R",AO7)))) -> wR | ... CS8: =IF($P8=0,CS7,IF(CS$3=$E8,IF($AA8=1,$F8&$AB8,$G8),IF(OR(CS$3=$D8,CS$3=$AC8,CS$3=$AE8),"",IF(CS$3=$AD8,$F8&"R",CS7)))) -> bR | CU8: bK | CV8: KING
A9: 4 | B9: =IF(Chess!$L$13="","",Chess!$L$13&"") | C9: =LOWER(SUBSTITUTE(SUBSTITUTE(SUBSTITUTE(SUBSTITUTE(TRIM($B9),"-",""),"=","")," ",""),"x","")) | D9: =IF(LEN($C9)<4,0,IFERROR(IF(AND(CODE(MID($C9,1,1))>=97,CODE(MID($C9,1,1))<=104,VALUE(MID($C9,2,1))>=1,VALUE(MID($C9,2,1))<=8),(VALUE(MID($C9,2,1))-1)*8+CODE(MID($C9,1,1))-96,0),0)) -> 0 | E9: =IF(LEN($C9)<4,0,IFERROR(IF(AND(CODE(MID($C9,3,1))>=97,CODE(MID($C9,3,1))<=104,VALUE(MID($C9,4,1))>=1,VALUE(MID($C9,4,1))<=8),(VALUE(MID($C9,4,1))-1)*8+CODE(MID($C9,3,1))-96,0),0)) -> 0 | F9: =IF(MOD(SUM($P$5:$P8),2)=0,"w","b") -> w | G9: =IF($D9=0,"",INDEX($AH8:$CS8,1,$D9)&"") | H9: =IF($E9=0,"",INDEX($AH8:$CS8,1,$E9)&"") | I9: =IF(OR($D9=0,$E9=0),0,MOD($E9-1,8)-MOD($D9-1,8)) -> 0 | J9: =IF(OR($D9=0,$E9=0),0,INT(($E9-1)/8)-INT(($D9-1)/8)) -> 0 | K9: =IF($G9="","",RIGHT($G9,1)) | L9: =IF(OR($D9=0,$E9=0),0,SUMPRODUCT(($AH$3:$CS$3>MIN($D9,$E9))*($AH$3:$CS$3<MAX($D9,$E9))*(MOD($AH$3:$CS$3-MIN($D9,$E9),MAX(1,ABS(SIGN($J9)*8+SIGN($I9))))=0)*($AH8:$CS8<>""))) -> 0 | M9: =IF($K9<>"K",0,IFERROR(--AND($J9=0,ABS($I9)=2,$D9=IF($F9="w",5,61),IF($F9="w",$S8,$V8)=0,IF($I9=2,AND(IF($F9="w",$U8,$X8)=0,INDEX($AH8:$CS8,1,$D9+1)&""="",INDEX($AH8:$CS8,1,$D9+2)&""=""),AND(IF($F9="w",$T8,$W8)=0,INDEX($AH8:$CS8,1,$D9-1)&""="",INDEX($AH8:$CS8,1,$D9-2)&""="",INDEX($AH8:$CS8,1,$D9-3)&""=""))),0)) -> 0 | N9: =IF($K9<>"P",0,IFERROR(--OR(AND($I9=0,$J9=IF($F9="w",1,-1),$H9=""),AND($I9=0,$J9=2*IF($F9="w",1,-1),$H9="",INT(($D9-1)/8)=IF($F9="w",1,6),INDEX($AH8:$CS8,1,MAX(1,MIN(64,$D9+8*IF($F9="w",1,-1))))&""=""),AND(ABS($I9)=1,$J9=IF($F9="w",1,-1),$H9<>""),AND(ABS($I9)=1,$J9=IF($F9="w",1,-1),$H9="",$R8>0,$E9=$R8)),0)) -> 0 | O9: =IF(OR($D9=0,$E9=0,$G9=""),0,IF($K9="N",--OR(AND(ABS($I9)=1,ABS($J9)=2),AND(ABS($I9)=2,ABS($J9)=1)),IF($K9="B",--AND(ABS($I9)=ABS($J9),$I9<>0,$L9=0),IF($K9="R",--AND(OR($I9=0,$J9=0),OR($I9<>0,$J9<>0),$L9=0),IF($K9="Q",--AND(OR(AND(ABS($I9)=ABS($J9),$I9<>0),AND(OR($I9=0,$J9=0),OR($I9<>0,$J9<>0))),$L9=0),IF($K9="K",--OR(MAX(ABS($I9),ABS($J9))=1,$M9=1),$N9)))))) -> 0 | P9: =IF($Q9="OK",1,0) -> 0 | Q9: =IF($B9="","",IF(OR(COUNTIF($AH8:$CS8,"wK")=0,COUNTIF($AH8:$CS8,"bK")=0),"Game is over",IF(OR($D9=0,$E9=0),"Use the format e2e4",IF($G9="","No piece on that square",IF(LEFT($G9,1)<>$F9,"Not your piece ("&IF($F9="w","White","Black")&" to move)",IF($D9=$E9,"Piece must move",IF(AND($H9<>"",LEFT($H9,1)=$F9),"Cannot capture your own piece",IF($O9=0,"Illegal move for that piece (or path blocked)","OK")))))))) | R9: =IF($P9=1,IF(AND($K9="P",ABS($J9)=2),($D9+$E9)/2,0),$R8) -> 0 | S9: =--OR($S8=1,AND($P9=1,OR($D9=5,$E9=5))) -> FALSE | T9: =--OR($T8=1,AND($P9=1,OR($D9=1,$E9=1))) -> FALSE | U9: =--OR($U8=1,AND($P9=1,OR($D9=8,$E9=8))) -> FALSE | V9: =--OR($V8=1,AND($P9=1,OR($D9=61,$E9=61))) -> FALSE | W9: =--OR($W8=1,AND($P9=1,OR($D9=57,$E9=57))) -> FALSE | X9: =--OR($X8=1,AND($P9=1,OR($D9=64,$E9=64))) -> FALSE | Y9: =--AND($P9=1,$K9="K",ABS($I9)=2) -> FALSE | Z9: =--AND($P9=1,$K9="P",ABS($I9)=1,$H9="") -> FALSE | AA9: =--AND($P9=1,$K9="P",INT(($E9-1)/8)=IF($F9="w",7,0)) -> FALSE | AB9: =IF(LEN($C9)>=5,IF(ISNUMBER(FIND(MID($C9,5,1),"qrbn")),UPPER(MID($C9,5,1)),"Q"),"Q") -> Q | AC9: =IF($Y9=1,IF($I9=2,$D9+3,$D9-4),0) -> 0 | AD9: =IF($Y9=1,IF($I9=2,$D9+1,$D9-1),0) -> 0 | AE9: =IF($Z9=1,$E9-8*IF($F9="w",1,-1),0) -> 0 | AF9: =IF($B9="","",IF($P9=1,LOWER(INDEX($CV$2:$CV$13,MATCH($G9,$CU$2:$CU$13,0)))&" "&MID("abcdefgh",MOD($D9-1,8)+1,1)&(INT(($D9-1)/8)+1)&"→"&MID("abcdefgh",MOD($E9-1,8)+1,1)&(INT(($E9-1)/8)+1)&IF(OR($H9<>"",$Z9=1)," ×","")&IF($Y9=1," castles","")&IF($Z9=1," e.p.","")&IF($AA9=1," =" &LOWER(INDEX($CV$2:$CV$13,MATCH($F9&$AB9,$CU$2:$CU$13,0))),""),"X "&$Q9)) | AH9: =IF($P9=0,AH8,IF(AH$3=$E9,IF($AA9=1,$F9&$AB9,$G9),IF(OR(AH$3=$D9,AH$3=$AC9,AH$3=$AE9),"",IF(AH$3=$AD9,$F9&"R",AH8)))) -> wR | AI9: =IF($P9=0,AI8,IF(AI$3=$E9,IF($AA9=1,$F9&$AB9,$G9),IF(OR(AI$3=$D9,AI$3=$AC9,AI$3=$AE9),"",IF(AI$3=$AD9,$F9&"R",AI8)))) -> wN | AJ9: =IF($P9=0,AJ8,IF(AJ$3=$E9,IF($AA9=1,$F9&$AB9,$G9),IF(OR(AJ$3=$D9,AJ$3=$AC9,AJ$3=$AE9),"",IF(AJ$3=$AD9,$F9&"R",AJ8)))) -> wB | AK9: =IF($P9=0,AK8,IF(AK$3=$E9,IF($AA9=1,$F9&$AB9,$G9),IF(OR(AK$3=$D9,AK$3=$AC9,AK$3=$AE9),"",IF(AK$3=$AD9,$F9&"R",AK8)))) -> wQ | AL9: =IF($P9=0,AL8,IF(AL$3=$E9,IF($AA9=1,$F9&$AB9,$G9),IF(OR(AL$3=$D9,AL$3=$AC9,AL$3=$AE9),"",IF(AL$3=$AD9,$F9&"R",AL8)))) -> wK | AM9: =IF($P9=0,AM8,IF(AM$3=$E9,IF($AA9=1,$F9&$AB9,$G9),IF(OR(AM$3=$D9,AM$3=$AC9,AM$3=$AE9),"",IF(AM$3=$AD9,$F9&"R",AM8)))) -> wB | AN9: =IF($P9=0,AN8,IF(AN$3=$E9,IF($AA9=1,$F9&$AB9,$G9),IF(OR(AN$3=$D9,AN$3=$AC9,AN$3=$AE9),"",IF(AN$3=$AD9,$F9&"R",AN8)))) -> wN | AO9: =IF($P9=0,AO8,IF(AO$3=$E9,IF($AA9=1,$F9&$AB9,$G9),IF(OR(AO$3=$D9,AO$3=$AC9,AO$3=$AE9),"",IF(AO$3=$AD9,$F9&"R",AO8)))) -> wR | ... CS9: =IF($P9=0,CS8,IF(CS$3=$E9,IF($AA9=1,$F9&$AB9,$G9),IF(OR(CS$3=$D9,CS$3=$AC9,CS$3=$AE9),"",IF(CS$3=$AD9,$F9&"R",CS8)))) -> bR | CU9: bQ | CV9: QUEEN
A10: 5 | B10: =IF(Chess!$L$14="","",Chess!$L$14&"") | C10: =LOWER(SUBSTITUTE(SUBSTITUTE(SUBSTITUTE(SUBSTITUTE(TRIM($B10),"-",""),"=","")," ",""),"x","")) | D10: =IF(LEN($C10)<4,0,IFERROR(IF(AND(CODE(MID($C10,1,1))>=97,CODE(MID($C10,1,1))<=104,VALUE(MID($C10,2,1))>=1,VALUE(MID($C10,2,1))<=8),(VALUE(MID($C10,2,1))-1)*8+CODE(MID($C10,1,1))-96,0),0)) -> 0 | E10: =IF(LEN($C10)<4,0,IFERROR(IF(AND(CODE(MID($C10,3,1))>=97,CODE(MID($C10,3,1))<=104,VALUE(MID($C10,4,1))>=1,VALUE(MID($C10,4,1))<=8),(VALUE(MID($C10,4,1))-1)*8+CODE(MID($C10,3,1))-96,0),0)) -> 0 | F10: =IF(MOD(SUM($P$5:$P9),2)=0,"w","b") -> w | G10: =IF($D10=0,"",INDEX($AH9:$CS9,1,$D10)&"") | H10: =IF($E10=0,"",INDEX($AH9:$CS9,1,$E10)&"") | I10: =IF(OR($D10=0,$E10=0),0,MOD($E10-1,8)-MOD($D10-1,8)) -> 0 | J10: =IF(OR($D10=0,$E10=0),0,INT(($E10-1)/8)-INT(($D10-1)/8)) -> 0 | K10: =IF($G10="","",RIGHT($G10,1)) | L10: =IF(OR($D10=0,$E10=0),0,SUMPRODUCT(($AH$3:$CS$3>MIN($D10,$E10))*($AH$3:$CS$3<MAX($D10,$E10))*(MOD($AH$3:$CS$3-MIN($D10,$E10),MAX(1,ABS(SIGN($J10)*8+SIGN($I10))))=0)*($AH9:$CS9<>""))) -> 0 | M10: =IF($K10<>"K",0,IFERROR(--AND($J10=0,ABS($I10)=2,$D10=IF($F10="w",5,61),IF($F10="w",$S9,$V9)=0,IF($I10=2,AND(IF($F10="w",$U9,$X9)=0,INDEX($AH9:$CS9,1,$D10+1)&""="",INDEX($AH9:$CS9,1,$D10+2)&""=""),AND(IF($F10="w",$T9,$W9)=0,INDEX($AH9:$CS9,1,$D10-1)&""="",INDEX($AH9:$CS9,1,$D10-2)&""="",INDEX($AH9:$CS9,1,$D10-3)&""=""))),0)) -> 0 | N10: =IF($K10<>"P",0,IFERROR(--OR(AND($I10=0,$J10=IF($F10="w",1,-1),$H10=""),AND($I10=0,$J10=2*IF($F10="w",1,-1),$H10="",INT(($D10-1)/8)=IF($F10="w",1,6),INDEX($AH9:$CS9,1,MAX(1,MIN(64,$D10+8*IF($F10="w",1,-1))))&""=""),AND(ABS($I10)=1,$J10=IF($F10="w",1,-1),$H10<>""),AND(ABS($I10)=1,$J10=IF($F10="w",1,-1),$H10="",$R9>0,$E10=$R9)),0)) -> 0 | O10: =IF(OR($D10=0,$E10=0,$G10=""),0,IF($K10="N",--OR(AND(ABS($I10)=1,ABS($J10)=2),AND(ABS($I10)=2,ABS($J10)=1)),IF($K10="B",--AND(ABS($I10)=ABS($J10),$I10<>0,$L10=0),IF($K10="R",--AND(OR($I10=0,$J10=0),OR($I10<>0,$J10<>0),$L10=0),IF($K10="Q",--AND(OR(AND(ABS($I10)=ABS($J10),$I10<>0),AND(OR($I10=0,$J10=0),OR($I10<>0,$J10<>0))),$L10=0),IF($K10="K",--OR(MAX(ABS($I10),ABS($J10))=1,$M10=1),$N10)))))) -> 0 | P10: =IF($Q10="OK",1,0) -> 0 | Q10: =IF($B10="","",IF(OR(COUNTIF($AH9:$CS9,"wK")=0,COUNTIF($AH9:$CS9,"bK")=0),"Game is over",IF(OR($D10=0,$E10=0),"Use the format e2e4",IF($G10="","No piece on that square",IF(LEFT($G10,1)<>$F10,"Not your piece ("&IF($F10="w","White","Black")&" to move)",IF($D10=$E10,"Piece must move",IF(AND($H10<>"",LEFT($H10,1)=$F10),"Cannot capture your own piece",IF($O10=0,"Illegal move for that piece (or path blocked)","OK")))))))) | R10: =IF($P10=1,IF(AND($K10="P",ABS($J10)=2),($D10+$E10)/2,0),$R9) -> 0 | S10: =--OR($S9=1,AND($P10=1,OR($D10=5,$E10=5))) -> FALSE | T10: =--OR($T9=1,AND($P10=1,OR($D10=1,$E10=1))) -> FALSE | U10: =--OR($U9=1,AND($P10=1,OR($D10=8,$E10=8))) -> FALSE | V10: =--OR($V9=1,AND($P10=1,OR($D10=61,$E10=61))) -> FALSE | W10: =--OR($W9=1,AND($P10=1,OR($D10=57,$E10=57))) -> FALSE | X10: =--OR($X9=1,AND($P10=1,OR($D10=64,$E10=64))) -> FALSE | Y10: =--AND($P10=1,$K10="K",ABS($I10)=2) -> FALSE | Z10: =--AND($P10=1,$K10="P",ABS($I10)=1,$H10="") -> FALSE | AA10: =--AND($P10=1,$K10="P",INT(($E10-1)/8)=IF($F10="w",7,0)) -> FALSE | AB10: =IF(LEN($C10)>=5,IF(ISNUMBER(FIND(MID($C10,5,1),"qrbn")),UPPER(MID($C10,5,1)),"Q"),"Q") -> Q | AC10: =IF($Y10=1,IF($I10=2,$D10+3,$D10-4),0) -> 0 | AD10: =IF($Y10=1,IF($I10=2,$D10+1,$D10-1),0) -> 0 | AE10: =IF($Z10=1,$E10-8*IF($F10="w",1,-1),0) -> 0 | AF10: =IF($B10="","",IF($P10=1,LOWER(INDEX($CV$2:$CV$13,MATCH($G10,$CU$2:$CU$13,0)))&" "&MID("abcdefgh",MOD($D10-1,8)+1,1)&(INT(($D10-1)/8)+1)&"→"&MID("abcdefgh",MOD($E10-1,8)+1,1)&(INT(($E10-1)/8)+1)&IF(OR($H10<>"",$Z10=1)," ×","")&IF($Y10=1," castles","")&IF($Z10=1," e.p.","")&IF($AA10=1," =" &LOWER(INDEX($CV$2:$CV$13,MATCH($F10&$AB10,$CU$2:$CU$13,0))),""),"X "&$Q10)) | AH10: =IF($P10=0,AH9,IF(AH$3=$E10,IF($AA10=1,$F10&$AB10,$G10),IF(OR(AH$3=$D10,AH$3=$AC10,AH$3=$AE10),"",IF(AH$3=$AD10,$F10&"R",AH9)))) -> wR | AI10: =IF($P10=0,AI9,IF(AI$3=$E10,IF($AA10=1,$F10&$AB10,$G10),IF(OR(AI$3=$D10,AI$3=$AC10,AI$3=$AE10),"",IF(AI$3=$AD10,$F10&"R",AI9)))) -> wN | AJ10: =IF($P10=0,AJ9,IF(AJ$3=$E10,IF($AA10=1,$F10&$AB10,$G10),IF(OR(AJ$3=$D10,AJ$3=$AC10,AJ$3=$AE10),"",IF(AJ$3=$AD10,$F10&"R",AJ9)))) -> wB | AK10: =IF($P10=0,AK9,IF(AK$3=$E10,IF($AA10=1,$F10&$AB10,$G10),IF(OR(AK$3=$D10,AK$3=$AC10,AK$3=$AE10),"",IF(AK$3=$AD10,$F10&"R",AK9)))) -> wQ | AL10: =IF($P10=0,AL9,IF(AL$3=$E10,IF($AA10=1,$F10&$AB10,$G10),IF(OR(AL$3=$D10,AL$3=$AC10,AL$3=$AE10),"",IF(AL$3=$AD10,$F10&"R",AL9)))) -> wK | AM10: =IF($P10=0,AM9,IF(AM$3=$E10,IF($AA10=1,$F10&$AB10,$G10),IF(OR(AM$3=$D10,AM$3=$AC10,AM$3=$AE10),"",IF(AM$3=$AD10,$F10&"R",AM9)))) -> wB | AN10: =IF($P10=0,AN9,IF(AN$3=$E10,IF($AA10=1,$F10&$AB10,$G10),IF(OR(AN$3=$D10,AN$3=$AC10,AN$3=$AE10),"",IF(AN$3=$AD10,$F10&"R",AN9)))) -> wN | AO10: =IF($P10=0,AO9,IF(AO$3=$E10,IF($AA10=1,$F10&$AB10,$G10),IF(OR(AO$3=$D10,AO$3=$AC10,AO$3=$AE10),"",IF(AO$3=$AD10,$F10&"R",AO9)))) -> wR | ... CS10: =IF($P10=0,CS9,IF(CS$3=$E10,IF($AA10=1,$F10&$AB10,$G10),IF(OR(CS$3=$D10,CS$3=$AC10,CS$3=$AE10),"",IF(CS$3=$AD10,$F10&"R",CS9)))) -> bR | CU10: bR | CV10: ROOK
A11: 6 | B11: =IF(Chess!$L$15="","",Chess!$L$15&"") | C11: =LOWER(SUBSTITUTE(SUBSTITUTE(SUBSTITUTE(SUBSTITUTE(TRIM($B11),"-",""),"=","")," ",""),"x","")) | D11: =IF(LEN($C11)<4,0,IFERROR(IF(AND(CODE(MID($C11,1,1))>=97,CODE(MID($C11,1,1))<=104,VALUE(MID($C11,2,1))>=1,VALUE(MID($C11,2,1))<=8),(VALUE(MID($C11,2,1))-1)*8+CODE(MID($C11,1,1))-96,0),0)) -> 0 | E11: =IF(LEN($C11)<4,0,IFERROR(IF(AND(CODE(MID($C11,3,1))>=97,CODE(MID($C11,3,1))<=104,VALUE(MID($C11,4,1))>=1,VALUE(MID($C11,4,1))<=8),(VALUE(MID($C11,4,1))-1)*8+CODE(MID($C11,3,1))-96,0),0)) -> 0 | F11: =IF(MOD(SUM($P$5:$P10),2)=0,"w","b") -> w | G11: =IF($D11=0,"",INDEX($AH10:$CS10,1,$D11)&"") | H11: =IF($E11=0,"",INDEX($AH10:$CS10,1,$E11)&"") | I11: =IF(OR($D11=0,$E11=0),0,MOD($E11-1,8)-MOD($D11-1,8)) -> 0 | J11: =IF(OR($D11=0,$E11=0),0,INT(($E11-1)/8)-INT(($D11-1)/8)) -> 0 | K11: =IF($G11="","",RIGHT($G11,1)) | L11: =IF(OR($D11=0,$E11=0),0,SUMPRODUCT(($AH$3:$CS$3>MIN($D11,$E11))*($AH$3:$CS$3<MAX($D11,$E11))*(MOD($AH$3:$CS$3-MIN($D11,$E11),MAX(1,ABS(SIGN($J11)*8+SIGN($I11))))=0)*($AH10:$CS10<>""))) -> 0 | M11: =IF($K11<>"K",0,IFERROR(--AND($J11=0,ABS($I11)=2,$D11=IF($F11="w",5,61),IF($F11="w",$S10,$V10)=0,IF($I11=2,AND(IF($F11="w",$U10,$X10)=0,INDEX($AH10:$CS10,1,$D11+1)&""="",INDEX($AH10:$CS10,1,$D11+2)&""=""),AND(IF($F11="w",$T10,$W10)=0,INDEX($AH10:$CS10,1,$D11-1)&""="",INDEX($AH10:$CS10,1,$D11-2)&""="",INDEX($AH10:$CS10,1,$D11-3)&""=""))),0)) -> 0 | N11: =IF($K11<>"P",0,IFERROR(--OR(AND($I11=0,$J11=IF($F11="w",1,-1),$H11=""),AND($I11=0,$J11=2*IF($F11="w",1,-1),$H11="",INT(($D11-1)/8)=IF($F11="w",1,6),INDEX($AH10:$CS10,1,MAX(1,MIN(64,$D11+8*IF($F11="w",1,-1))))&""=""),AND(ABS($I11)=1,$J11=IF($F11="w",1,-1),$H11<>""),AND(ABS($I11)=1,$J11=IF($F11="w",1,-1),$H11="",$R10>0,$E11=$R10)),0)) -> 0 | O11: =IF(OR($D11=0,$E11=0,$G11=""),0,IF($K11="N",--OR(AND(ABS($I11)=1,ABS($J11)=2),AND(ABS($I11)=2,ABS($J11)=1)),IF($K11="B",--AND(ABS($I11)=ABS($J11),$I11<>0,$L11=0),IF($K11="R",--AND(OR($I11=0,$J11=0),OR($I11<>0,$J11<>0),$L11=0),IF($K11="Q",--AND(OR(AND(ABS($I11)=ABS($J11),$I11<>0),AND(OR($I11=0,$J11=0),OR($I11<>0,$J11<>0))),$L11=0),IF($K11="K",--OR(MAX(ABS($I11),ABS($J11))=1,$M11=1),$N11)))))) -> 0 | P11: =IF($Q11="OK",1,0) -> 0 | Q11: =IF($B11="","",IF(OR(COUNTIF($AH10:$CS10,"wK")=0,COUNTIF($AH10:$CS10,"bK")=0),"Game is over",IF(OR($D11=0,$E11=0),"Use the format e2e4",IF($G11="","No piece on that square",IF(LEFT($G11,1)<>$F11,"Not your piece ("&IF($F11="w","White","Black")&" to move)",IF($D11=$E11,"Piece must move",IF(AND($H11<>"",LEFT($H11,1)=$F11),"Cannot capture your own piece",IF($O11=0,"Illegal move for that piece (or path blocked)","OK")))))))) | R11: =IF($P11=1,IF(AND($K11="P",ABS($J11)=2),($D11+$E11)/2,0),$R10) -> 0 | S11: =--OR($S10=1,AND($P11=1,OR($D11=5,$E11=5))) -> FALSE | T11: =--OR($T10=1,AND($P11=1,OR($D11=1,$E11=1))) -> FALSE | U11: =--OR($U10=1,AND($P11=1,OR($D11=8,$E11=8))) -> FALSE | V11: =--OR($V10=1,AND($P11=1,OR($D11=61,$E11=61))) -> FALSE | W11: =--OR($W10=1,AND($P11=1,OR($D11=57,$E11=57))) -> FALSE | X11: =--OR($X10=1,AND($P11=1,OR($D11=64,$E11=64))) -> FALSE | Y11: =--AND($P11=1,$K11="K",ABS($I11)=2) -> FALSE | Z11: =--AND($P11=1,$K11="P",ABS($I11)=1,$H11="") -> FALSE | AA11: =--AND($P11=1,$K11="P",INT(($E11-1)/8)=IF($F11="w",7,0)) -> FALSE | AB11: =IF(LEN($C11)>=5,IF(ISNUMBER(FIND(MID($C11,5,1),"qrbn")),UPPER(MID($C11,5,1)),"Q"),"Q") -> Q | AC11: =IF($Y11=1,IF($I11=2,$D11+3,$D11-4),0) -> 0 | AD11: =IF($Y11=1,IF($I11=2,$D11+1,$D11-1),0) -> 0 | AE11: =IF($Z11=1,$E11-8*IF($F11="w",1,-1),0) -> 0 | AF11: =IF($B11="","",IF($P11=1,LOWER(INDEX($CV$2:$CV$13,MATCH($G11,$CU$2:$CU$13,0)))&" "&MID("abcdefgh",MOD($D11-1,8)+1,1)&(INT(($D11-1)/8)+1)&"→"&MID("abcdefgh",MOD($E11-1,8)+1,1)&(INT(($E11-1)/8)+1)&IF(OR($H11<>"",$Z11=1)," ×","")&IF($Y11=1," castles","")&IF($Z11=1," e.p.","")&IF($AA11=1," =" &LOWER(INDEX($CV$2:$CV$13,MATCH($F11&$AB11,$CU$2:$CU$13,0))),""),"X "&$Q11)) | AH11: =IF($P11=0,AH10,IF(AH$3=$E11,IF($AA11=1,$F11&$AB11,$G11),IF(OR(AH$3=$D11,AH$3=$AC11,AH$3=$AE11),"",IF(AH$3=$AD11,$F11&"R",AH10)))) -> wR | AI11: =IF($P11=0,AI10,IF(AI$3=$E11,IF($AA11=1,$F11&$AB11,$G11),IF(OR(AI$3=$D11,AI$3=$AC11,AI$3=$AE11),"",IF(AI$3=$AD11,$F11&"R",AI10)))) -> wN | AJ11: =IF($P11=0,AJ10,IF(AJ$3=$E11,IF($AA11=1,$F11&$AB11,$G11),IF(OR(AJ$3=$D11,AJ$3=$AC11,AJ$3=$AE11),"",IF(AJ$3=$AD11,$F11&"R",AJ10)))) -> wB | AK11: =IF($P11=0,AK10,IF(AK$3=$E11,IF($AA11=1,$F11&$AB11,$G11),IF(OR(AK$3=$D11,AK$3=$AC11,AK$3=$AE11),"",IF(AK$3=$AD11,$F11&"R",AK10)))) -> wQ | AL11: =IF($P11=0,AL10,IF(AL$3=$E11,IF($AA11=1,$F11&$AB11,$G11),IF(OR(AL$3=$D11,AL$3=$AC11,AL$3=$AE11),"",IF(AL$3=$AD11,$F11&"R",AL10)))) -> wK | AM11: =IF($P11=0,AM10,IF(AM$3=$E11,IF($AA11=1,$F11&$AB11,$G11),IF(OR(AM$3=$D11,AM$3=$AC11,AM$3=$AE11),"",IF(AM$3=$AD11,$F11&"R",AM10)))) -> wB | AN11: =IF($P11=0,AN10,IF(AN$3=$E11,IF($AA11=1,$F11&$AB11,$G11),IF(OR(AN$3=$D11,AN$3=$AC11,AN$3=$AE11),"",IF(AN$3=$AD11,$F11&"R",AN10)))) -> wN | AO11: =IF($P11=0,AO10,IF(AO$3=$E11,IF($AA11=1,$F11&$AB11,$G11),IF(OR(AO$3=$D11,AO$3=$AC11,AO$3=$AE11),"",IF(AO$3=$AD11,$F11&"R",AO10)))) -> wR | ... CS11: =IF($P11=0,CS10,IF(CS$3=$E11,IF($AA11=1,$F11&$AB11,$G11),IF(OR(CS$3=$D11,CS$3=$AC11,CS$3=$AE11),"",IF(CS$3=$AD11,$F11&"R",CS10)))) -> bR | CU11: bB | CV11: BISHOP
A12: 7 | B12: =IF(Chess!$L$16="","",Chess!$L$16&"") | C12: =LOWER(SUBSTITUTE(SUBSTITUTE(SUBSTITUTE(SUBSTITUTE(TRIM($B12),"-",""),"=","")," ",""),"x","")) | D12: =IF(LEN($C12)<4,0,IFERROR(IF(AND(CODE(MID($C12,1,1))>=97,CODE(MID($C12,1,1))<=104,VALUE(MID($C12,2,1))>=1,VALUE(MID($C12,2,1))<=8),(VALUE(MID($C12,2,1))-1)*8+CODE(MID($C12,1,1))-96,0),0)) -> 0 | E12: =IF(LEN($C12)<4,0,IFERROR(IF(AND(CODE(MID($C12,3,1))>=97,CODE(MID($C12,3,1))<=104,VALUE(MID($C12,4,1))>=1,VALUE(MID($C12,4,1))<=8),(VALUE(MID($C12,4,1))-1)*8+CODE(MID($C12,3,1))-96,0),0)) -> 0 | F12: =IF(MOD(SUM($P$5:$P11),2)=0,"w","b") -> w | G12: =IF($D12=0,"",INDEX($AH11:$CS11,1,$D12)&"") | H12: =IF($E12=0,"",INDEX($AH11:$CS11,1,$E12)&"") | I12: =IF(OR($D12=0,$E12=0),0,MOD($E12-1,8)-MOD($D12-1,8)) -> 0 | J12: =IF(OR($D12=0,$E12=0),0,INT(($E12-1)/8)-INT(($D12-1)/8)) -> 0 | K12: =IF($G12="","",RIGHT($G12,1)) | L12: =IF(OR($D12=0,$E12=0),0,SUMPRODUCT(($AH$3:$CS$3>MIN($D12,$E12))*($AH$3:$CS$3<MAX($D12,$E12))*(MOD($AH$3:$CS$3-MIN($D12,$E12),MAX(1,ABS(SIGN($J12)*8+SIGN($I12))))=0)*($AH11:$CS11<>""))) -> 0 | M12: =IF($K12<>"K",0,IFERROR(--AND($J12=0,ABS($I12)=2,$D12=IF($F12="w",5,61),IF($F12="w",$S11,$V11)=0,IF($I12=2,AND(IF($F12="w",$U11,$X11)=0,INDEX($AH11:$CS11,1,$D12+1)&""="",INDEX($AH11:$CS11,1,$D12+2)&""=""),AND(IF($F12="w",$T11,$W11)=0,INDEX($AH11:$CS11,1,$D12-1)&""="",INDEX($AH11:$CS11,1,$D12-2)&""="",INDEX($AH11:$CS11,1,$D12-3)&""=""))),0)) -> 0 | N12: =IF($K12<>"P",0,IFERROR(--OR(AND($I12=0,$J12=IF($F12="w",1,-1),$H12=""),AND($I12=0,$J12=2*IF($F12="w",1,-1),$H12="",INT(($D12-1)/8)=IF($F12="w",1,6),INDEX($AH11:$CS11,1,MAX(1,MIN(64,$D12+8*IF($F12="w",1,-1))))&""=""),AND(ABS($I12)=1,$J12=IF($F12="w",1,-1),$H12<>""),AND(ABS($I12)=1,$J12=IF($F12="w",1,-1),$H12="",$R11>0,$E12=$R11)),0)) -> 0 | O12: =IF(OR($D12=0,$E12=0,$G12=""),0,IF($K12="N",--OR(AND(ABS($I12)=1,ABS($J12)=2),AND(ABS($I12)=2,ABS($J12)=1)),IF($K12="B",--AND(ABS($I12)=ABS($J12),$I12<>0,$L12=0),IF($K12="R",--AND(OR($I12=0,$J12=0),OR($I12<>0,$J12<>0),$L12=0),IF($K12="Q",--AND(OR(AND(ABS($I12)=ABS($J12),$I12<>0),AND(OR($I12=0,$J12=0),OR($I12<>0,$J12<>0))),$L12=0),IF($K12="K",--OR(MAX(ABS($I12),ABS($J12))=1,$M12=1),$N12)))))) -> 0 | P12: =IF($Q12="OK",1,0) -> 0 | Q12: =IF($B12="","",IF(OR(COUNTIF($AH11:$CS11,"wK")=0,COUNTIF($AH11:$CS11,"bK")=0),"Game is over",IF(OR($D12=0,$E12=0),"Use the format e2e4",IF($G12="","No piece on that square",IF(LEFT($G12,1)<>$F12,"Not your piece ("&IF($F12="w","White","Black")&" to move)",IF($D12=$E12,"Piece must move",IF(AND($H12<>"",LEFT($H12,1)=$F12),"Cannot capture your own piece",IF($O12=0,"Illegal move for that piece (or path blocked)","OK")))))))) | R12: =IF($P12=1,IF(AND($K12="P",ABS($J12)=2),($D12+$E12)/2,0),$R11) -> 0 | S12: =--OR($S11=1,AND($P12=1,OR($D12=5,$E12=5))) -> FALSE | T12: =--OR($T11=1,AND($P12=1,OR($D12=1,$E12=1))) -> FALSE | U12: =--OR($U11=1,AND($P12=1,OR($D12=8,$E12=8))) -> FALSE | V12: =--OR($V11=1,AND($P12=1,OR($D12=61,$E12=61))) -> FALSE | W12: =--OR($W11=1,AND($P12=1,OR($D12=57,$E12=57))) -> FALSE | X12: =--OR($X11=1,AND($P12=1,OR($D12=64,$E12=64))) -> FALSE | Y12: =--AND($P12=1,$K12="K",ABS($I12)=2) -> FALSE | Z12: =--AND($P12=1,$K12="P",ABS($I12)=1,$H12="") -> FALSE | AA12: =--AND($P12=1,$K12="P",INT(($E12-1)/8)=IF($F12="w",7,0)) -> FALSE | AB12: =IF(LEN($C12)>=5,IF(ISNUMBER(FIND(MID($C12,5,1),"qrbn")),UPPER(MID($C12,5,1)),"Q"),"Q") -> Q | AC12: =IF($Y12=1,IF($I12=2,$D12+3,$D12-4),0) -> 0 | AD12: =IF($Y12=1,IF($I12=2,$D12+1,$D12-1),0) -> 0 | AE12: =IF($Z12=1,$E12-8*IF($F12="w",1,-1),0) -> 0 | AF12: =IF($B12="","",IF($P12=1,LOWER(INDEX($CV$2:$CV$13,MATCH($G12,$CU$2:$CU$13,0)))&" "&MID("abcdefgh",MOD($D12-1,8)+1,1)&(INT(($D12-1)/8)+1)&"→"&MID("abcdefgh",MOD($E12-1,8)+1,1)&(INT(($E12-1)/8)+1)&IF(OR($H12<>"",$Z12=1)," ×","")&IF($Y12=1," castles","")&IF($Z12=1," e.p.","")&IF($AA12=1," =" &LOWER(INDEX($CV$2:$CV$13,MATCH($F12&$AB12,$CU$2:$CU$13,0))),""),"X "&$Q12)) | AH12: =IF($P12=0,AH11,IF(AH$3=$E12,IF($AA12=1,$F12&$AB12,$G12),IF(OR(AH$3=$D12,AH$3=$AC12,AH$3=$AE12),"",IF(AH$3=$AD12,$F12&"R",AH11)))) -> wR | AI12: =IF($P12=0,AI11,IF(AI$3=$E12,IF($AA12=1,$F12&$AB12,$G12),IF(OR(AI$3=$D12,AI$3=$AC12,AI$3=$AE12),"",IF(AI$3=$AD12,$F12&"R",AI11)))) -> wN | AJ12: =IF($P12=0,AJ11,IF(AJ$3=$E12,IF($AA12=1,$F12&$AB12,$G12),IF(OR(AJ$3=$D12,AJ$3=$AC12,AJ$3=$AE12),"",IF(AJ$3=$AD12,$F12&"R",AJ11)))) -> wB | AK12: =IF($P12=0,AK11,IF(AK$3=$E12,IF($AA12=1,$F12&$AB12,$G12),IF(OR(AK$3=$D12,AK$3=$AC12,AK$3=$AE12),"",IF(AK$3=$AD12,$F12&"R",AK11)))) -> wQ | AL12: =IF($P12=0,AL11,IF(AL$3=$E12,IF($AA12=1,$F12&$AB12,$G12),IF(OR(AL$3=$D12,AL$3=$AC12,AL$3=$AE12),"",IF(AL$3=$AD12,$F12&"R",AL11)))) -> wK | AM12: =IF($P12=0,AM11,IF(AM$3=$E12,IF($AA12=1,$F12&$AB12,$G12),IF(OR(AM$3=$D12,AM$3=$AC12,AM$3=$AE12),"",IF(AM$3=$AD12,$F12&"R",AM11)))) -> wB | AN12: =IF($P12=0,AN11,IF(AN$3=$E12,IF($AA12=1,$F12&$AB12,$G12),IF(OR(AN$3=$D12,AN$3=$AC12,AN$3=$AE12),"",IF(AN$3=$AD12,$F12&"R",AN11)))) -> wN | AO12: =IF($P12=0,AO11,IF(AO$3=$E12,IF($AA12=1,$F12&$AB12,$G12),IF(OR(AO$3=$D12,AO$3=$AC12,AO$3=$AE12),"",IF(AO$3=$AD12,$F12&"R",AO11)))) -> wR | ... CS12: =IF($P12=0,CS11,IF(CS$3=$E12,IF($AA12=1,$F12&$AB12,$G12),IF(OR(CS$3=$D12,CS$3=$AC12,CS$3=$AE12),"",IF(CS$3=$AD12,$F12&"R",CS11)))) -> bR | CU12: bN | CV12: KNIGHT
A13: 8 | B13: =IF(Chess!$L$17="","",Chess!$L$17&"") | C13: =LOWER(SUBSTITUTE(SUBSTITUTE(SUBSTITUTE(SUBSTITUTE(TRIM($B13),"-",""),"=","")," ",""),"x","")) | D13: =IF(LEN($C13)<4,0,IFERROR(IF(AND(CODE(MID($C13,1,1))>=97,CODE(MID($C13,1,1))<=104,VALUE(MID($C13,2,1))>=1,VALUE(MID($C13,2,1))<=8),(VALUE(MID($C13,2,1))-1)*8+CODE(MID($C13,1,1))-96,0),0)) -> 0 | E13: =IF(LEN($C13)<4,0,IFERROR(IF(AND(CODE(MID($C13,3,1))>=97,CODE(MID($C13,3,1))<=104,VALUE(MID($C13,4,1))>=1,VALUE(MID($C13,4,1))<=8),(VALUE(MID($C13,4,1))-1)*8+CODE(MID($C13,3,1))-96,0),0)) -> 0 | F13: =IF(MOD(SUM($P$5:$P12),2)=0,"w","b") -> w | G13: =IF($D13=0,"",INDEX($AH12:$CS12,1,$D13)&"") | H13: =IF($E13=0,"",INDEX($AH12:$CS12,1,$E13)&"") | I13: =IF(OR($D13=0,$E13=0),0,MOD($E13-1,8)-MOD($D13-1,8)) -> 0 | J13: =IF(OR($D13=0,$E13=0),0,INT(($E13-1)/8)-INT(($D13-1)/8)) -> 0 | K13: =IF($G13="","",RIGHT($G13,1)) | L13: =IF(OR($D13=0,$E13=0),0,SUMPRODUCT(($AH$3:$CS$3>MIN($D13,$E13))*($AH$3:$CS$3<MAX($D13,$E13))*(MOD($AH$3:$CS$3-MIN($D13,$E13),MAX(1,ABS(SIGN($J13)*8+SIGN($I13))))=0)*($AH12:$CS12<>""))) -> 0 | M13: =IF($K13<>"K",0,IFERROR(--AND($J13=0,ABS($I13)=2,$D13=IF($F13="w",5,61),IF($F13="w",$S12,$V12)=0,IF($I13=2,AND(IF($F13="w",$U12,$X12)=0,INDEX($AH12:$CS12,1,$D13+1)&""="",INDEX($AH12:$CS12,1,$D13+2)&""=""),AND(IF($F13="w",$T12,$W12)=0,INDEX($AH12:$CS12,1,$D13-1)&""="",INDEX($AH12:$CS12,1,$D13-2)&""="",INDEX($AH12:$CS12,1,$D13-3)&""=""))),0)) -> 0 | N13: =IF($K13<>"P",0,IFERROR(--OR(AND($I13=0,$J13=IF($F13="w",1,-1),$H13=""),AND($I13=0,$J13=2*IF($F13="w",1,-1),$H13="",INT(($D13-1)/8)=IF($F13="w",1,6),INDEX($AH12:$CS12,1,MAX(1,MIN(64,$D13+8*IF($F13="w",1,-1))))&""=""),AND(ABS($I13)=1,$J13=IF($F13="w",1,-1),$H13<>""),AND(ABS($I13)=1,$J13=IF($F13="w",1,-1),$H13="",$R12>0,$E13=$R12)),0)) -> 0 | O13: =IF(OR($D13=0,$E13=0,$G13=""),0,IF($K13="N",--OR(AND(ABS($I13)=1,ABS($J13)=2),AND(ABS($I13)=2,ABS($J13)=1)),IF($K13="B",--AND(ABS($I13)=ABS($J13),$I13<>0,$L13=0),IF($K13="R",--AND(OR($I13=0,$J13=0),OR($I13<>0,$J13<>0),$L13=0),IF($K13="Q",--AND(OR(AND(ABS($I13)=ABS($J13),$I13<>0),AND(OR($I13=0,$J13=0),OR($I13<>0,$J13<>0))),$L13=0),IF($K13="K",--OR(MAX(ABS($I13),ABS($J13))=1,$M13=1),$N13)))))) -> 0 | P13: =IF($Q13="OK",1,0) -> 0 | Q13: =IF($B13="","",IF(OR(COUNTIF($AH12:$CS12,"wK")=0,COUNTIF($AH12:$CS12,"bK")=0),"Game is over",IF(OR($D13=0,$E13=0),"Use the format e2e4",IF($G13="","No piece on that square",IF(LEFT($G13,1)<>$F13,"Not your piece ("&IF($F13="w","White","Black")&" to move)",IF($D13=$E13,"Piece must move",IF(AND($H13<>"",LEFT($H13,1)=$F13),"Cannot capture your own piece",IF($O13=0,"Illegal move for that piece (or path blocked)","OK")))))))) | R13: =IF($P13=1,IF(AND($K13="P",ABS($J13)=2),($D13+$E13)/2,0),$R12) -> 0 | S13: =--OR($S12=1,AND($P13=1,OR($D13=5,$E13=5))) -> FALSE | T13: =--OR($T12=1,AND($P13=1,OR($D13=1,$E13=1))) -> FALSE | U13: =--OR($U12=1,AND($P13=1,OR($D13=8,$E13=8))) -> FALSE | V13: =--OR($V12=1,AND($P13=1,OR($D13=61,$E13=61))) -> FALSE | W13: =--OR($W12=1,AND($P13=1,OR($D13=57,$E13=57))) -> FALSE | X13: =--OR($X12=1,AND($P13=1,OR($D13=64,$E13=64))) -> FALSE | Y13: =--AND($P13=1,$K13="K",ABS($I13)=2) -> FALSE | Z13: =--AND($P13=1,$K13="P",ABS($I13)=1,$H13="") -> FALSE | AA13: =--AND($P13=1,$K13="P",INT(($E13-1)/8)=IF($F13="w",7,0)) -> FALSE | AB13: =IF(LEN($C13)>=5,IF(ISNUMBER(FIND(MID($C13,5,1),"qrbn")),UPPER(MID($C13,5,1)),"Q"),"Q") -> Q | AC13: =IF($Y13=1,IF($I13=2,$D13+3,$D13-4),0) -> 0 | AD13: =IF($Y13=1,IF($I13=2,$D13+1,$D13-1),0) -> 0 | AE13: =IF($Z13=1,$E13-8*IF($F13="w",1,-1),0) -> 0 | AF13: =IF($B13="","",IF($P13=1,LOWER(INDEX($CV$2:$CV$13,MATCH($G13,$CU$2:$CU$13,0)))&" "&MID("abcdefgh",MOD($D13-1,8)+1,1)&(INT(($D13-1)/8)+1)&"→"&MID("abcdefgh",MOD($E13-1,8)+1,1)&(INT(($E13-1)/8)+1)&IF(OR($H13<>"",$Z13=1)," ×","")&IF($Y13=1," castles","")&IF($Z13=1," e.p.","")&IF($AA13=1," =" &LOWER(INDEX($CV$2:$CV$13,MATCH($F13&$AB13,$CU$2:$CU$13,0))),""),"X "&$Q13)) | AH13: =IF($P13=0,AH12,IF(AH$3=$E13,IF($AA13=1,$F13&$AB13,$G13),IF(OR(AH$3=$D13,AH$3=$AC13,AH$3=$AE13),"",IF(AH$3=$AD13,$F13&"R",AH12)))) -> wR | AI13: =IF($P13=0,AI12,IF(AI$3=$E13,IF($AA13=1,$F13&$AB13,$G13),IF(OR(AI$3=$D13,AI$3=$AC13,AI$3=$AE13),"",IF(AI$3=$AD13,$F13&"R",AI12)))) -> wN | AJ13: =IF($P13=0,AJ12,IF(AJ$3=$E13,IF($AA13=1,$F13&$AB13,$G13),IF(OR(AJ$3=$D13,AJ$3=$AC13,AJ$3=$AE13),"",IF(AJ$3=$AD13,$F13&"R",AJ12)))) -> wB | AK13: =IF($P13=0,AK12,IF(AK$3=$E13,IF($AA13=1,$F13&$AB13,$G13),IF(OR(AK$3=$D13,AK$3=$AC13,AK$3=$AE13),"",IF(AK$3=$AD13,$F13&"R",AK12)))) -> wQ | AL13: =IF($P13=0,AL12,IF(AL$3=$E13,IF($AA13=1,$F13&$AB13,$G13),IF(OR(AL$3=$D13,AL$3=$AC13,AL$3=$AE13),"",IF(AL$3=$AD13,$F13&"R",AL12)))) -> wK | AM13: =IF($P13=0,AM12,IF(AM$3=$E13,IF($AA13=1,$F13&$AB13,$G13),IF(OR(AM$3=$D13,AM$3=$AC13,AM$3=$AE13),"",IF(AM$3=$AD13,$F13&"R",AM12)))) -> wB | AN13: =IF($P13=0,AN12,IF(AN$3=$E13,IF($AA13=1,$F13&$AB13,$G13),IF(OR(AN$3=$D13,AN$3=$AC13,AN$3=$AE13),"",IF(AN$3=$AD13,$F13&"R",AN12)))) -> wN | AO13: =IF($P13=0,AO12,IF(AO$3=$E13,IF($AA13=1,$F13&$AB13,$G13),IF(OR(AO$3=$D13,AO$3=$AC13,AO$3=$AE13),"",IF(AO$3=$AD13,$F13&"R",AO12)))) -> wR | ... CS13: =IF($P13=0,CS12,IF(CS$3=$E13,IF($AA13=1,$F13&$AB13,$G13),IF(OR(CS$3=$D13,CS$3=$AC13,CS$3=$AE13),"",IF(CS$3=$AD13,$F13&"R",CS12)))) -> bR | CU13: bP | CV13: PAWN
A14: 9 | B14: =IF(Chess!$L$18="","",Chess!$L$18&"") | C14: =LOWER(SUBSTITUTE(SUBSTITUTE(SUBSTITUTE(SUBSTITUTE(TRIM($B14),"-",""),"=","")," ",""),"x","")) | D14: =IF(LEN($C14)<4,0,IFERROR(IF(AND(CODE(MID($C14,1,1))>=97,CODE(MID($C14,1,1))<=104,VALUE(MID($C14,2,1))>=1,VALUE(MID($C14,2,1))<=8),(VALUE(MID($C14,2,1))-1)*8+CODE(MID($C14,1,1))-96,0),0)) -> 0 | E14: =IF(LEN($C14)<4,0,IFERROR(IF(AND(CODE(MID($C14,3,1))>=97,CODE(MID($C14,3,1))<=104,VALUE(MID($C14,4,1))>=1,VALUE(MID($C14,4,1))<=8),(VALUE(MID($C14,4,1))-1)*8+CODE(MID($C14,3,1))-96,0),0)) -> 0 | F14: =IF(MOD(SUM($P$5:$P13),2)=0,"w","b") -> w | G14: =IF($D14=0,"",INDEX($AH13:$CS13,1,$D14)&"") | H14: =IF($E14=0,"",INDEX($AH13:$CS13,1,$E14)&"") | I14: =IF(OR($D14=0,$E14=0),0,MOD($E14-1,8)-MOD($D14-1,8)) -> 0 | J14: =IF(OR($D14=0,$E14=0),0,INT(($E14-1)/8)-INT(($D14-1)/8)) -> 0 | K14: =IF($G14="","",RIGHT($G14,1)) | L14: =IF(OR($D14=0,$E14=0),0,SUMPRODUCT(($AH$3:$CS$3>MIN($D14,$E14))*($AH$3:$CS$3<MAX($D14,$E14))*(MOD($AH$3:$CS$3-MIN($D14,$E14),MAX(1,ABS(SIGN($J14)*8+SIGN($I14))))=0)*($AH13:$CS13<>""))) -> 0 | M14: =IF($K14<>"K",0,IFERROR(--AND($J14=0,ABS($I14)=2,$D14=IF($F14="w",5,61),IF($F14="w",$S13,$V13)=0,IF($I14=2,AND(IF($F14="w",$U13,$X13)=0,INDEX($AH13:$CS13,1,$D14+1)&""="",INDEX($AH13:$CS13,1,$D14+2)&""=""),AND(IF($F14="w",$T13,$W13)=0,INDEX($AH13:$CS13,1,$D14-1)&""="",INDEX($AH13:$CS13,1,$D14-2)&""="",INDEX($AH13:$CS13,1,$D14-3)&""=""))),0)) -> 0 | N14: =IF($K14<>"P",0,IFERROR(--OR(AND($I14=0,$J14=IF($F14="w",1,-1),$H14=""),AND($I14=0,$J14=2*IF($F14="w",1,-1),$H14="",INT(($D14-1)/8)=IF($F14="w",1,6),INDEX($AH13:$CS13,1,MAX(1,MIN(64,$D14+8*IF($F14="w",1,-1))))&""=""),AND(ABS($I14)=1,$J14=IF($F14="w",1,-1),$H14<>""),AND(ABS($I14)=1,$J14=IF($F14="w",1,-1),$H14="",$R13>0,$E14=$R13)),0)) -> 0 | O14: =IF(OR($D14=0,$E14=0,$G14=""),0,IF($K14="N",--OR(AND(ABS($I14)=1,ABS($J14)=2),AND(ABS($I14)=2,ABS($J14)=1)),IF($K14="B",--AND(ABS($I14)=ABS($J14),$I14<>0,$L14=0),IF($K14="R",--AND(OR($I14=0,$J14=0),OR($I14<>0,$J14<>0),$L14=0),IF($K14="Q",--AND(OR(AND(ABS($I14)=ABS($J14),$I14<>0),AND(OR($I14=0,$J14=0),OR($I14<>0,$J14<>0))),$L14=0),IF($K14="K",--OR(MAX(ABS($I14),ABS($J14))=1,$M14=1),$N14)))))) -> 0 | P14: =IF($Q14="OK",1,0) -> 0 | Q14: =IF($B14="","",IF(OR(COUNTIF($AH13:$CS13,"wK")=0,COUNTIF($AH13:$CS13,"bK")=0),"Game is over",IF(OR($D14=0,$E14=0),"Use the format e2e4",IF($G14="","No piece on that square",IF(LEFT($G14,1)<>$F14,"Not your piece ("&IF($F14="w","White","Black")&" to move)",IF($D14=$E14,"Piece must move",IF(AND($H14<>"",LEFT($H14,1)=$F14),"Cannot capture your own piece",IF($O14=0,"Illegal move for that piece (or path blocked)","OK")))))))) | R14: =IF($P14=1,IF(AND($K14="P",ABS($J14)=2),($D14+$E14)/2,0),$R13) -> 0 | S14: =--OR($S13=1,AND($P14=1,OR($D14=5,$E14=5))) -> FALSE | T14: =--OR($T13=1,AND($P14=1,OR($D14=1,$E14=1))) -> FALSE | U14: =--OR($U13=1,AND($P14=1,OR($D14=8,$E14=8))) -> FALSE | V14: =--OR($V13=1,AND($P14=1,OR($D14=61,$E14=61))) -> FALSE | W14: =--OR($W13=1,AND($P14=1,OR($D14=57,$E14=57))) -> FALSE | X14: =--OR($X13=1,AND($P14=1,OR($D14=64,$E14=64))) -> FALSE | Y14: =--AND($P14=1,$K14="K",ABS($I14)=2) -> FALSE | Z14: =--AND($P14=1,$K14="P",ABS($I14)=1,$H14="") -> FALSE | AA14: =--AND($P14=1,$K14="P",INT(($E14-1)/8)=IF($F14="w",7,0)) -> FALSE | AB14: =IF(LEN($C14)>=5,IF(ISNUMBER(FIND(MID($C14,5,1),"qrbn")),UPPER(MID($C14,5,1)),"Q"),"Q") -> Q | AC14: =IF($Y14=1,IF($I14=2,$D14+3,$D14-4),0) -> 0 | AD14: =IF($Y14=1,IF($I14=2,$D14+1,$D14-1),0) -> 0 | AE14: =IF($Z14=1,$E14-8*IF($F14="w",1,-1),0) -> 0 | AF14: =IF($B14="","",IF($P14=1,LOWER(INDEX($CV$2:$CV$13,MATCH($G14,$CU$2:$CU$13,0)))&" "&MID("abcdefgh",MOD($D14-1,8)+1,1)&(INT(($D14-1)/8)+1)&"→"&MID("abcdefgh",MOD($E14-1,8)+1,1)&(INT(($E14-1)/8)+1)&IF(OR($H14<>"",$Z14=1)," ×","")&IF($Y14=1," castles","")&IF($Z14=1," e.p.","")&IF($AA14=1," =" &LOWER(INDEX($CV$2:$CV$13,MATCH($F14&$AB14,$CU$2:$CU$13,0))),""),"X "&$Q14)) | AH14: =IF($P14=0,AH13,IF(AH$3=$E14,IF($AA14=1,$F14&$AB14,$G14),IF(OR(AH$3=$D14,AH$3=$AC14,AH$3=$AE14),"",IF(AH$3=$AD14,$F14&"R",AH13)))) -> wR | AI14: =IF($P14=0,AI13,IF(AI$3=$E14,IF($AA14=1,$F14&$AB14,$G14),IF(OR(AI$3=$D14,AI$3=$AC14,AI$3=$AE14),"",IF(AI$3=$AD14,$F14&"R",AI13)))) -> wN | AJ14: =IF($P14=0,AJ13,IF(AJ$3=$E14,IF($AA14=1,$F14&$AB14,$G14),IF(OR(AJ$3=$D14,AJ$3=$AC14,AJ$3=$AE14),"",IF(AJ$3=$AD14,$F14&"R",AJ13)))) -> wB | AK14: =IF($P14=0,AK13,IF(AK$3=$E14,IF($AA14=1,$F14&$AB14,$G14),IF(OR(AK$3=$D14,AK$3=$AC14,AK$3=$AE14),"",IF(AK$3=$AD14,$F14&"R",AK13)))) -> wQ | AL14: =IF($P14=0,AL13,IF(AL$3=$E14,IF($AA14=1,$F14&$AB14,$G14),IF(OR(AL$3=$D14,AL$3=$AC14,AL$3=$AE14),"",IF(AL$3=$AD14,$F14&"R",AL13)))) -> wK | AM14: =IF($P14=0,AM13,IF(AM$3=$E14,IF($AA14=1,$F14&$AB14,$G14),IF(OR(AM$3=$D14,AM$3=$AC14,AM$3=$AE14),"",IF(AM$3=$AD14,$F14&"R",AM13)))) -> wB | AN14: =IF($P14=0,AN13,IF(AN$3=$E14,IF($AA14=1,$F14&$AB14,$G14),IF(OR(AN$3=$D14,AN$3=$AC14,AN$3=$AE14),"",IF(AN$3=$AD14,$F14&"R",AN13)))) -> wN | AO14: =IF($P14=0,AO13,IF(AO$3=$E14,IF($AA14=1,$F14&$AB14,$G14),IF(OR(AO$3=$D14,AO$3=$AC14,AO$3=$AE14),"",IF(AO$3=$AD14,$F14&"R",AO13)))) -> wR | ... CS14: =IF($P14=0,CS13,IF(CS$3=$E14,IF($AA14=1,$F14&$AB14,$G14),IF(OR(CS$3=$D14,CS$3=$AC14,CS$3=$AE14),"",IF(CS$3=$AD14,$F14&"R",CS13)))) -> bR
